Workbook

Sheet data
B2: 3-Player Simultaneous Game
B3: where each of the three players has three options: A1, A2,, A3 for A, B1, B2, B3 for B, C1, C2,C3 for C.
B4: please fill in the payoff values into the blue fields
C6: A1
C7: C1 | F7: C2 | I7: C3
B8: B1 | C8: 1 | D8: 1 | E8: 2 | F8: 3 | G8: 1 | H8: 2 | I8: 5 | J8: 0 | K8: 0
B9: B2 | C9: 3 | D9: 2 | E9: 1 | F9: 3 | G9: 0 | H9: 1 | I9: 1 | J9: 1 | K9: 2
B10: B3 | C10: 2 | D10: 2 | E10: 2 | F10: 1 | G10: -1 | H10: 2 | I10: 1 | J10: 0 | K10: 0
C13: A2
C14: C1 | F14: C2 | I14: C3
B15: B1 | C15: 1 | D15: 1 | E15: 1 | F15: 1 | G15: 3 | H15: 2 | I15: -1 | J15: 0 | K15: 0
B16: B2 | C16: 1 | D16: 2 | E16: 1 | F16: -1 | G16: 0 | H16: 3 | I16: 1 | J16: 1 | K16: 2
B17: B3 | C17: -1 | D17: 2 | E17: 0 | F17: 1 | G17: 1 | H17: 2 | I17: -1 | J17: 0 | K17: 0
C20: A3
C21: C1 | F21: C2 | I21: C3
B22: B1 | C22: 1 | D22: 3 | E22: 1 | F22: 1 | G22: 1 | H22: 4 | I22: -1 | J22: 0 | K22: 0
B23: B2 | C23: 1 | D23: 2 | E23: 1 | F23: -1 | G23: 1 | H23: 2 | I23: 1 | J23: 1 | K23: 2
B24: B3 | C24: -1 | D24: 1 | E24: 0 | F24: 1 | G24: -1 | H24: 2 | I24: -1 | J24: 0 | K24: 0

Sheet maximin
B2: The Maximin moves are colored in orange
C4: A1
C5: C1 | F5: C2 | I5: C3 | M5: A1 | N5: =MIN(C6,F6,I6,C7,F7,I7,C8,F8,I8) -> 1 | O5: =MAX(N5,N6,N7) -> 1
B6: B1 | C6: =data!C8 -> 1 | D6: =data!D8 -> 1 | E6: =data!E8 -> 2 | F6: =data!F8 -> 3 | G6: =data!G8 -> 1 | H6: =data!H8 -> 2 | I6: =data!I8 -> 5 | J6: =data!J8 -> 0 | K6: =data!K8 -> 0 | M6: A2 | N6: =MIN(C13,F13,I13,C14,F14,I14,C15,F15,I15) -> -1
B7: B2 | C7: =data!C9 -> 3 | D7: =data!D9 -> 2 | E7: =data!E9 -> 1 | F7: =data!F9 -> 3 | G7: =data!G9 -> 0 | H7: =data!H9 -> 1 | I7: =data!I9 -> 1 | J7: =data!J9 -> 1 | K7: =data!K9 -> 2 | M7: A3 | N7: =MIN(C20,F20,I20,C21,F21,I21,C22,F22,I22) -> -1
B8: B3 | C8: =data!C10 -> 2 | D8: =data!D10 -> 2 | E8: =data!E10 -> 2 | F8: =data!F10 -> 1 | G8: =data!G10 -> -1 | H8: =data!H10 -> 2 | I8: =data!I10 -> 1 | J8: =data!J10 -> 0 | K8: =data!K10 -> 0 | M8: B1 | N8: =MIN(D6,G6,J6,D13,G13,J13,D20,G20,J20) -> 0 | O8: =MAX(N8,N9,N10) -> 0
M9: B2 | N9: =MIN(D7,G7,J7,D14,G14,J14,D21,G21,J21) -> 0
M10: B3 | N10: =MIN(D8,G8,J8,D15,G15,J15,D22,G22,J22) -> -1
C11: A2 | M11: C1 | N11: =MIN(E6,E7,E8,E13,E14,E15,E20,E21,E22) -> 0 | O11: =MAX(N11,N12,N13) -> 1
C12: C1 | F12: C2 | I12: C3 | M12: C2 | N12: =MIN(H6,H7,H8,H13,H14,H15,H20,H21,H22) -> 1
B13: B1 | C13: =data!C15 -> 1 | D13: =data!D15 -> 1 | E13: =data!E15 -> 1 | F13: =data!F15 -> 1 | G13: =data!G15 -> 3 | H13: =data!H15 -> 2 | I13: =data!I15 -> -1 | J13: =data!J15 -> 0 | K13: =data!K15 -> 0 | M13: C3 | N13: =MIN(K6,K7,K8,K13,K14,K15,K20,K21,K22) -> 0
B14: B2 | C14: =data!C16 -> 1 | D14: =data!D16 -> 2 | E14: =data!E16 -> 1 | F14: =data!F16 -> -1 | G14: =data!G16 -> 0 | H14: =data!H16 -> 3 | I14: =data!I16 -> 1 | J14: =data!J16 -> 1 | K14: =data!K16 -> 2
B15: B3 | C15: =data!C17 -> -1 | D15: =data!D17 -> 2 | E15: =data!E17 -> 0 | F15: =data!F17 -> 1 | G15: =data!G17 -> 1 | H15: =data!H17 -> 2 | I15: =data!I17 -> -1 | J15: =data!J17 -> 0 | K15: =data!K17 -> 0
C18: A3
C19: C1 | F19: C2 | I19: C3
B20: B1 | C20: =data!C22 -> 1 | D20: =data!D22 -> 3 | E20: =data!E22 -> 1 | F20: =data!F22 -> 1 | G20: =data!G22 -> 1 | H20: =data!H22 -> 4 | I20: =data!I22 -> -1 | J20: =data!J22 -> 0 | K20: =data!K22 -> 0
B21: B2 | C21: =data!C23 -> 1 | D21: =data!D23 -> 2 | E21: =data!E23 -> 1 | F21: =data!F23 -> -1 | G21: =data!G23 -> 1 | H21: =data!H23 -> 2 | I21: =data!I23 -> 1 | J21: =data!J23 -> 1 | K21: =data!K23 -> 2
B22: B3 | C22: =data!C24 -> -1 | D22: =data!D24 -> 1 | E22: =data!E24 -> 0 | F22: =data!F24 -> 1 | G22: =data!G24 -> -1 | H22: =data!H24 -> 2 | I22: =data!I24 -> -1 | J22: =data!J24 -> 0 | K22: =data!K24 -> 0

Sheet pure Nash
B2: The Nash equilibria oucome cells are colored in (two shades of) green.
C4: A1
C5: C1 | F5: C2 | I5: C3
B6: B1 | C6: =data!C8 -> 1 | D6: =data!D8 -> 1 | E6: =data!E8 -> 2 | F6: =data!F8 -> 3 | G6: =data!G8 -> 1 | H6: =data!H8 -> 2 | I6: =data!I8 -> 5 | J6: =data!J8 -> 0 | K6: =data!K8 -> 0
B7: B2 | C7: =data!C9 -> 3 | D7: =data!D9 -> 2 | E7: =data!E9 -> 1 | F7: =data!F9 -> 3 | G7: =data!G9 -> 0 | H7: =data!H9 -> 1 | I7: =data!I9 -> 1 | J7: =data!J9 -> 1 | K7: =data!K9 -> 2
B8: B3 | C8: =data!C10 -> 2 | D8: =data!D10 -> 2 | E8: =data!E10 -> 2 | F8: =data!F10 -> 1 | G8: =data!G10 -> -1 | H8: =data!H10 -> 2 | I8: =data!I10 -> 1 | J8: =data!J10 -> 0 | K8: =data!K10 -> 0
C11: A2
C12: C1 | F12: C2 | I12: C3
B13: B1 | C13: =data!C15 -> 1 | D13: =data!D15 -> 1 | E13: =data!E15 -> 1 | F13: =data!F15 -> 1 | G13: =data!G15 -> 3 | H13: =data!H15 -> 2 | I13: =data!I15 -> -1 | J13: =data!J15 -> 0 | K13: =data!K15 -> 0
B14: B2 | C14: =data!C16 -> 1 | D14: =data!D16 -> 2 | E14: =data!E16 -> 1 | F14: =data!F16 -> -1 | G14: =data!G16 -> 0 | H14: =data!H16 -> 3 | I14: =data!I16 -> 1 | J14: =data!J16 -> 1 | K14: =data!K16 -> 2
B15: B3 | C15: =data!C17 -> -1 | D15: =data!D17 -> 2 | E15: =data!E17 -> 0 | F15: =data!F17 -> 1 | G15: =data!G17 -> 1 | H15: =data!H17 -> 2 | I15: =data!I17 -> -1 | J15: =data!J17 -> 0 | K15: =data!K17 -> 0
C18: A3
C19: C1 | F19: C2 | I19: C3
B20: B1 | C20: =data!C22 -> 1 | D20: =data!D22 -> 3 | E20: =data!E22 -> 1 | F20: =data!F22 -> 1 | G20: =data!G22 -> 1 | H20: =data!H22 -> 4 | I20: =data!I22 -> -1 | J20: =data!J22 -> 0 | K20: =data!K22 -> 0
B21: B2 | C21: =data!C23 -> 1 | D21: =data!D23 -> 2 | E21: =data!E23 -> 1 | F21: =data!F23 -> -1 | G21: =data!G23 -> 1 | H21: =data!H23 -> 2 | I21: =data!I23 -> 1 | J21: =data!J23 -> 1 | K21: =data!K23 -> 2
B22: B3 | C22: =data!C24 -> -1 | D22: =data!D24 -> 1 | E22: =data!E24 -> 0 | F22: =data!F24 -> 1 | G22: =data!G24 -> -1 | H22: =data!H24 -> 2 | I22: =data!I24 -> -1 | J22: =data!J24 -> 0 | K22: =data!K24 -> 0
F26: Best response
B27: A | C27: B | D27: C | F27: A | G27: B | H27: C | J27: A | K27: B | L27: C
B28: 1 | C28: 1 | D28: 1 | F28: =CONCATENATE(IF(C6>=MAX(C6,C13,C20),"1",""),IF(C13>=MAX(C6,C13,C20),"2",""),IF(C20>=MAX(C6,C13,C20),"3","")) -> 123 | G28: =CONCATENATE(IF(D6>=MAX(D6,D7,D8),"1",""),IF(D7>=MAX(D6,D7,D8),"2",""),IF(D8>=MAX(D6,D7,D8),"3","")) -> 23 | H28: =CONCATENATE(IF(E6>=MAX(E6,H6,K6),"1",""),IF(H6>=MAX(E6,H6,K6),"2",""),IF(K6>=MAX(E6,H6,K6),"3","")) -> 12 | J28: =IF(FIND(B28,CONCATENATE(REPT(F28,3),123),1)<4,"yes","no") -> yes | K28: =IF(FIND(C28,CONCATENATE(REPT(G28,3),123),1)<4,"yes","no") -> no | L28: =IF(FIND(D28,CONCATENATE(REPT(H28,3),123),1)<4,"yes","no") -> yes | N28: =IF(AND(J28="yes",K28="yes",L28="yes"),"Nash equilibrium","")
B29: 1 | C29: 1 | D29: 2 | F29: =CONCATENATE(IF(F6>=MAX(F6,F13,F20),"1",""),IF(F13>=MAX(F6,F13,F20),"2",""),IF(F20>=MAX(F6,F13,F20),"3","")) -> 1 | G29: =CONCATENATE(IF(G6>=MAX(G6,G7,G8),"1",""),IF(G7>=MAX(G6,G7,G8),"2",""),IF(G8>=MAX(G6,G7,G8),"3","")) -> 1 | H29: =CONCATENATE(IF(E6>=MAX(E6,H6,K6),"1",""),IF(H6>=MAX(E6,H6,K6),"2",""),IF(K6>=MAX(E6,H6,K6),"3","")) -> 12 | J29: =IF(FIND(B29,CONCATENATE(REPT(F29,3),123),1)<4,"yes","no") -> yes | K29: =IF(FIND(C29,CONCATENATE(REPT(G29,3),123),1)<4,"yes","no") -> yes | L29: =IF(FIND(D29,CONCATENATE(REPT(H29,3),123),1)<4,"yes","no") -> yes | N29: =IF(AND(J29="yes",K29="yes",L29="yes"),"Nash equilibrium","") -> Nash equilibrium
B30: 1 | C30: 1 | D30: 3 | F30: =CONCATENATE(IF(I6>=MAX(I6,I13,I20),"1",""),IF(I13>=MAX(I6,I13,I20),"2",""),IF(I20>=MAX(I6,I13,I20),"3","")) -> 1 | G30: =CONCATENATE(IF(J6>=MAX(J6,J7,J8),"1",""),IF(J7>=MAX(J6,J7,J8),"2",""),IF(J8>=MAX(J6,J7,J8),"3","")) -> 2 | H30: =CONCATENATE(IF(E6>=MAX(E6,H6,K6),"1",""),IF(H6>=MAX(E6,H6,K6),"2",""),IF(K6>=MAX(E6,H6,K6),"3","")) -> 12 | J30: =IF(FIND(B30,CONCATENATE(REPT(F30,3),123),1)<4,"yes","no") -> yes | K30: =IF(FIND(C30,CONCATENATE(REPT(G30,3),123),1)<4,"yes","no") -> no | L30: =IF(FIND(D30,CONCATENATE(REPT(H30,3),123),1)<4,"yes","no") -> no | N30: =IF(AND(J30="yes",K30="yes",L30="yes"),"Nash equilibrium","")
B31: 1 | C31: 2 | D31: 1 | F31: =CONCATENATE(IF(C7>=MAX(C7,C14,C21),"1",""),IF(C14>=MAX(C7,C14,C21),"2",""),IF(C21>=MAX(C7,C14,C21),"3","")) -> 1 | G31: =CONCATENATE(IF(D6>=MAX(D6,D7,D8),"1",""),IF(D7>=MAX(D6,D7,D8),"2",""),IF(D8>=MAX(D6,D7,D8),"3","")) -> 23 | H31: =CONCATENATE(IF(E7>=MAX(E7,H7,K7),"1",""),IF(H7>=MAX(E7,H7,K7),"2",""),IF(K7>=MAX(E7,H7,K7),"3","")) -> 3 | J31: =IF(FIND(B31,CONCATENATE(REPT(F31,3),123),1)<4,"yes","no") -> yes | K31: =IF(FIND(C31,CONCATENATE(REPT(G31,3),123),1)<4,"yes","no") -> yes | L31: =IF(FIND(D31,CONCATENATE(REPT(H31,3),123),1)<4,"yes","no") -> no | N31: =IF(AND(J31="yes",K31="yes",L31="yes"),"Nash equilibrium","")
B32: 1 | C32: 2 | D32: 2 | F32: =CONCATENATE(IF(F7>=MAX(F7,F14,F21),"1",""),IF(F14>=MAX(F7,F14,F21),"2",""),IF(F21>=MAX(F7,F14,F21),"3","")) -> 1 | G32: =CONCATENATE(IF(G6>=MAX(G6,G7,G8),"1",""),IF(G7>=MAX(G6,G7,G8),"2",""),IF(G8>=MAX(G6,G7,G8),"3","")) -> 1 | H32: =CONCATENATE(IF(E7>=MAX(E7,H7,K7),"1",""),IF(H7>=MAX(E7,H7,K7),"2",""),IF(K7>=MAX(E7,H7,K7),"3","")) -> 3 | J32: =IF(FIND(B32,CONCATENATE(REPT(F32,3),123),1)<4,"yes","no") -> yes | K32: =IF(FIND(C32,CONCATENATE(REPT(G32,3),123),1)<4,"yes","no") -> no | L32: =IF(FIND(D32,CONCATENATE(REPT(H32,3),123),1)<4,"yes","no") -> no | N32: =IF(AND(J32="yes",K32="yes",L32="yes"),"Nash equilibrium","")
B33: 1 | C33: 2 | D33: 3 | F33: =CONCATENATE(IF(I7>=MAX(I7,I14,I21),"1",""),IF(I14>=MAX(I7,I14,I21),"2",""),IF(I21>=MAX(I7,I14,I21),"3","")) -> 123 | G33: =CONCATENATE(IF(J6>=MAX(J6,J7,J8),"1",""),IF(J7>=MAX(J6,J7,J8),"2",""),IF(J8>=MAX(J6,J7,J8),"3","")) -> 2 | H33: =CONCATENATE(IF(E7>=MAX(E7,H7,K7),"1",""),IF(H7>=MAX(E7,H7,K7),"2",""),IF(K7>=MAX(E7,H7,K7),"3","")) -> 3 | J33: =IF(FIND(B33,CONCATENATE(REPT(F33,3),123),1)<4,"yes","no") -> yes | K33: =IF(FIND(C33,CONCATENATE(REPT(G33,3),123),1)<4,"yes","no") -> yes | L33: =IF(FIND(D33,CONCATENATE(REPT(H33,3),123),1)<4,"yes","no") -> yes | N33: =IF(AND(J33="yes",K33="yes",L33="yes"),"Nash equilibrium","") -> Nash equilibrium
B34: 1 | C34: 3 | D34: 1 | F34: =CONCATENATE(IF(C8>=MAX(C8,C15,C22),"1",""),IF(C15>=MAX(C8,C15,C22),"2",""),IF(C22>=MAX(C8,C15,C22),"3","")) -> 1 | G34: =CONCATENATE(IF(D6>=MAX(D6,D7,D8),"1",""),IF(D7>=MAX(D6,D7,D8),"2",""),IF(D8>=MAX(D6,D7,D8),"3","")) -> 23 | H34: =CONCATENATE(IF(E8>=MAX(E8,H8,K8),"1",""),IF(H8>=MAX(E8,H8,K8),"2",""),IF(K8>=MAX(E8,H8,K8),"3","")) -> 12 | J34: =IF(FIND(B34,CONCATENATE(REPT(F34,3),123),1)<4,"yes","no") -> yes | K34: =IF(FIND(C34,CONCATENATE(REPT(G34,3),123),1)<4,"yes","no") -> yes | L34: =IF(FIND(D34,CONCATENATE(REPT(H34,3),123),1)<4,"yes","no") -> yes | N34: =IF(AND(J34="yes",K34="yes",L34="yes"),"Nash equilibrium","") -> Nash equilibrium
B35: 1 | C35: 3 | D35: 2 | F35: =CONCATENATE(IF(F8>=MAX(F8,F15,F22),"1",""),IF(F15>=MAX(F8,F15,F22),"2",""),IF(F22>=MAX(F8,F15,F22),"3","")) -> 123 | G35: =CONCATENATE(IF(G6>=MAX(G6,G7,G8),"1",""),IF(G7>=MAX(G6,G7,G8),"2",""),IF(G8>=MAX(G6,G7,G8),"3","")) -> 1 | H35: =CONCATENATE(IF(E8>=MAX(E8,H8,K8),"1",""),IF(H8>=MAX(E8,H8,K8),"2",""),IF(K8>=MAX(E8,H8,K8),"3","")) -> 12 | J35: =IF(FIND(B35,CONCATENATE(REPT(F35,3),123),1)<4,"yes","no") -> yes | K35: =IF(FIND(C35,CONCATENATE(REPT(G35,3),123),1)<4,"yes","no") -> no | L35: =IF(FIND(D35,CONCATENATE(REPT(H35,3),123),1)<4,"yes","no") -> yes | N35: =IF(AND(J35="yes",K35="yes",L35="yes"),"Nash equilibrium","")
B36: 1 | C36: 3 | D36: 3 | F36: =CONCATENATE(IF(I8>=MAX(I8,I15,I22),"1",""),IF(I15>=MAX(I8,I15,I22),"2",""),IF(I22>=MAX(I8,I15,I22),"3","")) -> 1 | G36: =CONCATENATE(IF(J6>=MAX(J6,J7,J8),"1",""),IF(J7>=MAX(J6,J7,J8),"2",""),IF(J8>=MAX(J6,J7,J8),"3","")) -> 2 | H36: =CONCATENATE(IF(E8>=MAX(E8,H8,K8),"1",""),IF(H8>=MAX(E8,H8,K8),"2",""),IF(K8>=MAX(E8,H8,K8),"3","")) -> 12 | J36: =IF(FIND(B36,CONCATENATE(REPT(F36,3),123),1)<4,"yes","no") -> yes | K36: =IF(FIND(C36,CONCATENATE(REPT(G36,3),123),1)<4,"yes","no") -> no | L36: =IF(FIND(D36,CONCATENATE(REPT(H36,3),123),1)<4,"yes","no") -> no | N36: =IF(AND(J36="yes",K36="yes",L36="yes"),"Nash equilibrium","")
B37: 2 | C37: 1 | D37: 1 | F37: =CONCATENATE(IF(C6>=MAX(C6,C13,C20),"1",""),IF(C13>=MAX(C6,C13,C20),"2",""),IF(C20>=MAX(C6,C13,C20),"3","")) -> 123 | G37: =CONCATENATE(IF(D13>=MAX(D13,D14,D15),"1",""),IF(D14>=MAX(D13,D14,D15),"2",""),IF(D15>=MAX(D13,D14,D15),"3","")) -> 23 | H37: =CONCATENATE(IF(E13>=MAX(E13,H13,K13),"1",""),IF(H13>=MAX(E13,H13,K13),"2",""),IF(K13>=MAX(E13,H13,K13),"3","")) -> 2 | J37: =IF(FIND(B37,CONCATENATE(REPT(F37,3),123),1)<4,"yes","no") -> yes | K37: =IF(FIND(C37,CONCATENATE(REPT(G37,3),123),1)<4,"yes","no") -> no | L37: =IF(FIND(D37,CONCATENATE(REPT(H37,3),123),1)<4,"yes","no") -> no | N37: =IF(AND(J37="yes",K37="yes",L37="yes"),"Nash equilibrium","")
B38: 2 | C38: 1 | D38: 2 | F38: =CONCATENATE(IF(F6>=MAX(F6,F13,F20),"1",""),IF(F13>=MAX(F6,F13,F20),"2",""),IF(F20>=MAX(F6,F13,F20),"3","")) -> 1 | G38: =CONCATENATE(IF(G13>=MAX(G13,G14,G15),"1",""),IF(G14>=MAX(G13,G14,G15),"2",""),IF(G15>=MAX(G13,G14,G15),"3","")) -> 1 | H38: =CONCATENATE(IF(E13>=MAX(E13,H13,K13),"1",""),IF(H13>=MAX(E13,H13,K13),"2",""),IF(K13>=MAX(E13,H13,K13),"3","")) -> 2 | J38: =IF(FIND(B38,CONCATENATE(REPT(F38,3),123),1)<4,"yes","no") -> no | K38: =IF(FIND(C38,CONCATENATE(REPT(G38,3),123),1)<4,"yes","no") -> yes | L38: =IF(FIND(D38,CONCATENATE(REPT(H38,3),123),1)<4,"yes","no") -> yes | N38: =IF(AND(J38="yes",K38="yes",L38="yes"),"Nash equilibrium","")
B39: 2 | C39: 1 | D39: 3 | F39: =CONCATENATE(IF(I6>=MAX(I6,I13,I20),"1",""),IF(I13>=MAX(I6,I13,I20),"2",""),IF(I20>=MAX(I6,I13,I20),"3","")) -> 1 | G39: =CONCATENATE(IF(J13>=MAX(J13,J14,J15),"1",""),IF(J14>=MAX(J13,J14,J15),"2",""),IF(J15>=MAX(J13,J14,J15),"3","")) -> 2 | H39: =CONCATENATE(IF(E13>=MAX(E13,H13,K13),"1",""),IF(H13>=MAX(E13,H13,K13),"2",""),IF(K13>=MAX(E13,H13,K13),"3","")) -> 2 | J39: =IF(FIND(B39,CONCATENATE(REPT(F39,3),123),1)<4,"yes","no") -> no | K39: =IF(FIND(C39,CONCATENATE(REPT(G39,3),123),1)<4,"yes","no") -> no | L39: =IF(FIND(D39,CONCATENATE(REPT(H39,3),123),1)<4,"yes","no") -> no | N39: =IF(AND(J39="yes",K39="yes",L39="yes"),"Nash equilibrium","")
B40: 2 | C40: 2 | D40: 1 | F40: =CONCATENATE(IF(C7>=MAX(C7,C14,C21),"1",""),IF(C14>=MAX(C7,C14,C21),"2",""),IF(C21>=MAX(C7,C14,C21),"3","")) -> 1 | G40: =CONCATENATE(IF(D13>=MAX(D13,D14,D15),"1",""),IF(D14>=MAX(D13,D14,D15),"2",""),IF(D15>=MAX(D13,D14,D15),"3","")) -> 23 | H40: =CONCATENATE(IF(E14>=MAX(E14,H14,K14),"1",""),IF(H14>=MAX(E14,H14,K14),"2",""),IF(K14>=MAX(E14,H14,K14),"3","")) -> 2 | J40: =IF(FIND(B40,CONCATENATE(REPT(F40,3),123),1)<4,"yes","no") -> no | K40: =IF(FIND(C40,CONCATENATE(REPT(G40,3),123),1)<4,"yes","no") -> yes | L40: =IF(FIND(D40,CONCATENATE(REPT(H40,3),123),1)<4,"yes","no") -> no | N40: =IF(AND(J40="yes",K40="yes",L40="yes"),"Nash equilibrium","")
B41: 2 | C41: 2 | D41: 2 | F41: =CONCATENATE(IF(F7>=MAX(F7,F14,F21),"1",""),IF(F14>=MAX(F7,F14,F21),"2",""),IF(F21>=MAX(F7,F14,F21),"3","")) -> 1 | G41: =CONCATENATE(IF(G13>=MAX(G13,G14,G15),"1",""),IF(G14>=MAX(G13,G14,G15),"2",""),IF(G15>=MAX(G13,G14,G15),"3","")) -> 1 | H41: =CONCATENATE(IF(E14>=MAX(E14,H14,K14),"1",""),IF(H14>=MAX(E14,H14,K14),"2",""),IF(K14>=MAX(E14,H14,K14),"3","")) -> 2 | J41: =IF(FIND(B41,CONCATENATE(REPT(F41,3),123),1)<4,"yes","no") -> no | K41: =IF(FIND(C41,CONCATENATE(REPT(G41,3),123),1)<4,"yes","no") -> no | L41: =IF(FIND(D41,CONCATENATE(REPT(H41,3),123),1)<4,"yes","no") -> yes | N41: =IF(AND(J41="yes",K41="yes",L41="yes"),"Nash equilibrium","")
B42: 2 | C42: 2 | D42: 3 | F42: =CONCATENATE(IF(I7>=MAX(I7,I14,I21),"1",""),IF(I14>=MAX(I7,I14,I21),"2",""),IF(I21>=MAX(I7,I14,I21),"3","")) -> 123 | G42: =CONCATENATE(IF(J13>=MAX(J13,J14,J15),"1",""),IF(J14>=MAX(J13,J14,J15),"2",""),IF(J15>=MAX(J13,J14,J15),"3","")) -> 2 | H42: =CONCATENATE(IF(E14>=MAX(E14,H14,K14),"1",""),IF(H14>=MAX(E14,H14,K14),"2",""),IF(K14>=MAX(E14,H14,K14),"3","")) -> 2 | J42: =IF(FIND(B42,CONCATENATE(REPT(F42,3),123),1)<4,"yes","no") -> yes | K42: =IF(FIND(C42,CONCATENATE(REPT(G42,3),123),1)<4,"yes","no") -> yes | L42: =IF(FIND(D42,CONCATENATE(REPT(H42,3),123),1)<4,"yes","no") -> no | N42: =IF(AND(J42="yes",K42="yes",L42="yes"),"Nash equilibrium","")
B43: 2 | C43: 3 | D43: 1 | F43: =CONCATENATE(IF(C8>=MAX(C8,C15,C22),"1",""),IF(C15>=MAX(C8,C15,C22),"2",""),IF(C22>=MAX(C8,C15,C22),"3","")) -> 1 | G43: =CONCATENATE(IF(D13>=MAX(D13,D14,D15),"1",""),IF(D14>=MAX(D13,D14,D15),"2",""),IF(D15>=MAX(D13,D14,D15),"3","")) -> 23 | H43: =CONCATENATE(IF(E15>=MAX(E15,H15,K15),"1",""),IF(H15>=MAX(E15,H15,K15),"2",""),IF(K15>=MAX(E15,H15,K15),"3","")) -> 2 | J43: =IF(FIND(B43,CONCATENATE(REPT(F43,3),123),1)<4,"yes","no") -> no | K43: =IF(FIND(C43,CONCATENATE(REPT(G43,3),123),1)<4,"yes","no") -> yes | L43: =IF(FIND(D43,CONCATENATE(REPT(H43,3),123),1)<4,"yes","no") -> no | N43: =IF(AND(J43="yes",K43="yes",L43="yes"),"Nash equilibrium","")
B44: 2 | C44: 3 | D44: 2 | F44: =CONCATENATE(IF(F8>=MAX(F8,F15,F22),"1",""),IF(F15>=MAX(F8,F15,F22),"2",""),IF(F22>=MAX(F8,F15,F22),"3","")) -> 123 | G44: =CONCATENATE(IF(G13>=MAX(G13,G14,G15),"1",""),IF(G14>=MAX(G13,G14,G15),"2",""),IF(G15>=MAX(G13,G14,G15),"3","")) -> 1 | H44: =CONCATENATE(IF(E15>=MAX(E15,H15,K15),"1",""),IF(H15>=MAX(E15,H15,K15),"2",""),IF(K15>=MAX(E15,H15,K15),"3","")) -> 2 | J44: =IF(FIND(B44,CONCATENATE(REPT(F44,3),123),1)<4,"yes","no") -> yes | K44: =IF(FIND(C44,CONCATENATE(REPT(G44,3),123),1)<4,"yes","no") -> no | L44: =IF(FIND(D44,CONCATENATE(REPT(H44,3),123),1)<4,"yes","no") -> yes | N44: =IF(AND(J44="yes",K44="yes",L44="yes"),"Nash equilibrium","")
B45: 2 | C45: 3 | D45: 3 | F45: =CONCATENATE(IF(I8>=MAX(I8,I15,I22),"1",""),IF(I15>=MAX(I8,I15,I22),"2",""),IF(I22>=MAX(I8,I15,I22),"3","")) -> 1 | G45: =CONCATENATE(IF(J13>=MAX(J13,J14,J15),"1",""),IF(J14>=MAX(J13,J14,J15),"2",""),IF(J15>=MAX(J13,J14,J15),"3","")) -> 2 | H45: =CONCATENATE(IF(E15>=MAX(E15,H15,K15),"1",""),IF(H15>=MAX(E15,H15,K15),"2",""),IF(K15>=MAX(E15,H15,K15),"3","")) -> 2 | J45: =IF(FIND(B45,CONCATENATE(REPT(F45,3),123),1)<4,"yes","no") -> no | K45: =IF(FIND(C45,CONCATENATE(REPT(G45,3),123),1)<4,"yes","no") -> no | L45: =IF(FIND(D45,CONCATENATE(REPT(H45,3),123),1)<4,"yes","no") -> no | N45: =IF(AND(J45="yes",K45="yes",L45="yes"),"Nash equilibrium","")
B46: 3 | C46: 1 | D46: 1 | F46: =CONCATENATE(IF(C6>=MAX(C6,C13,C20),"1",""),IF(C13>=MAX(C6,C13,C20),"2",""),IF(C20>=MAX(C6,C13,C20),"3","")) -> 123 | G46: =CONCATENATE(IF(D20>=MAX(D20,D21,D22),"1",""),IF(D21>=MAX(D20,D21,D22),"2",""),IF(D22>=MAX(D20,D21,D22),"3","")) -> 1 | H46: =CONCATENATE(IF(E20>=MAX(E20,H20,K20),"1",""),IF(H20>=MAX(E20,H20,K20),"2",""),IF(K20>=MAX(E20,H20,K20),"3","")) -> 2 | J46: =IF(FIND(B46,CONCATENATE(REPT(F46,3),123),1)<4,"yes","no") -> yes | K46: =IF(FIND(C46,CONCATENATE(REPT(G46,3),123),1)<4,"yes","no") -> yes | L46: =IF(FIND(D46,CONCATENATE(REPT(H46,3),123),1)<4,"yes","no") -> no | N46: =IF(AND(J46="yes",K46="yes",L46="yes"),"Nash equilibrium","")
B47: 3 | C47: 1 | D47: 2 | F47: =CONCATENATE(IF(F6>=MAX(F6,F13,F20),"1",""),IF(F13>=MAX(F6,F13,F20),"2",""),IF(F20>=MAX(F6,F13,F20),"3","")) -> 1 | G47: =CONCATENATE(IF(G20>=MAX(G20,G21,G22),"1",""),IF(G21>=MAX(G20,G21,G22),"2",""),IF(G22>=MAX(G20,G21,G22),"3","")) -> 12 | H47: =CONCATENATE(IF(E20>=MAX(E20,H20,K20),"1",""),IF(H20>=MAX(E20,H20,K20),"2",""),IF(K20>=MAX(E20,H20,K20),"3","")) -> 2 | J47: =IF(FIND(B47,CONCATENATE(REPT(F47,3),123),1)<4,"yes","no") -> no | K47: =IF(FIND(C47,CONCATENATE(REPT(G47,3),123),1)<4,"yes","no") -> yes | L47: =IF(FIND(D47,CONCATENATE(REPT(H47,3),123),1)<4,"yes","no") -> yes | N47: =IF(AND(J47="yes",K47="yes",L47="yes"),"Nash equilibrium","")
B48: 3 | C48: 1 | D48: 3 | F48: =CONCATENATE(IF(I6>=MAX(I6,I13,I20),"1",""),IF(I13>=MAX(I6,I13,I20),"2",""),IF(I20>=MAX(I6,I13,I20),"3","")) -> 1 | G48: =CONCATENATE(IF(J20>=MAX(J20,J21,J22),"1",""),IF(J21>=MAX(J20,J21,J22),"2",""),IF(J22>=MAX(J20,J21,J22),"3","")) -> 2 | H48: =CONCATENATE(IF(E20>=MAX(E20,H20,K20),"1",""),IF(H20>=MAX(E20,H20,K20),"2",""),IF(K20>=MAX(E20,H20,K20),"3","")) -> 2 | J48: =IF(FIND(B48,CONCATENATE(REPT(F48,3),123),1)<4,"yes","no") -> no | K48: =IF(FIND(C48,CONCATENATE(REPT(G48,3),123),1)<4,"yes","no") -> no | L48: =IF(FIND(D48,CONCATENATE(REPT(H48,3),123),1)<4,"yes","no") -> no | N48: =IF(AND(J48="yes",K48="yes",L48="yes"),"Nash equilibrium","")
B49: 3 | C49: 2 | D49: 1 | F49: =CONCATENATE(IF(C7>=MAX(C7,C14,C21),"1",""),IF(C14>=MAX(C7,C14,C21),"2",""),IF(C21>=MAX(C7,C14,C21),"3","")) -> 1 | G49: =CONCATENATE(IF(D20>=MAX(D20,D21,D22),"1",""),IF(D21>=MAX(D20,D21,D22),"2",""),IF(D22>=MAX(D20,D21,D22),"3","")) -> 1 | H49: =CONCATENATE(IF(E21>=MAX(E21,H21,K21),"1",""),IF(H21>=MAX(E21,H21,K21),"2",""),IF(K21>=MAX(E21,H21,K21),"3","")) -> 23 | J49: =IF(FIND(B49,CONCATENATE(REPT(F49,3),123),1)<4,"yes","no") -> no | K49: =IF(FIND(C49,CONCATENATE(REPT(G49,3),123),1)<4,"yes","no") -> no | L49: =IF(FIND(D49,CONCATENATE(REPT(H49,3),123),1)<4,"yes","no") -> no | N49: =IF(AND(J49="yes",K49="yes",L49="yes"),"Nash equilibrium","")
...
