Workbook

Sheet data
E1: Zero-sum Simultaneous Game
B2: Please write your matrix (payoffs for the row player Ann) into the blue cells. If your matrix is smaller than 21*21, just leave the other fields blank.
C4: the matrix
C5: 1 | D5: 2 | E5: 3 | F5: 4 | G5: 5 | H5: 6 | I5: 7 | J5: 8 | K5: 9 | L5: 10 | M5: 11 | N5: 12 | O5: 13 | P5: 14 | Q5: 15 | R5: 16 | S5: 17 | T5: 18 | U5: 19 | V5: 20 | W5: 21
C6: B1 | D6: B2 | E6: B3 | F6: B4 | G6: B5 | H6: B6 | I6: B7 | J6: B8 | K6: B9 | L6: B10 | M6: B11 | N6: B12 | O6: B13 | P6: B14 | Q6: B15 | R6: B16 | S6: B17 | T6: B18 | U6: B19 | V6: B20 | W6: B21
A7: 1 | B7: A1
A8: 2 | B8: A2
A9: 3 | B9: A3
A10: 4 | B10: A4
A11: 5 | B11: A5
A12: 6 | B12: A6
A13: 7 | B13: A7
A14: 8 | B14: A8
A15: 9 | B15: A9
A16: 10 | B16: A10
A17: 11 | B17: A11
A18: 12 | B18: A12
... A27: 21 | B27: A21

Sheet non-zero-sum
G1: The non-zero-sum representation
C4: the matrix
C5: 1 | D5: 1 | E5: 2 | F5: 2 | G5: 3 | H5: 3 | I5: 4 | J5: 4 | K5: 5 | L5: 5 | M5: 6 | N5: 6 | O5: 7 | P5: 7 | Q5: 8 | R5: 8 | S5: 9 | T5: 9 | U5: 10 | V5: 10 | W5: 11 | X5: 11 | Y5: 12 | Z5: 12 | AA5: 13 | AB5: 13 | AC5: 14 | AD5: 14 | AE5: 15 | AF5: 15 | AG5: 16 | AH5: 16 | AI5: 17 | AJ5: 17 | AK5: 18 | AL5: 18 | AM5: 19 | AN5: 19 | AO5: 20 | AP5: 20 | AQ5: 21 | AR5: 21
C6: B1 | D6: B1 | E6: B2 | F6: B2 | G6: B3 | H6: B3 | I6: B4 | J6: B4 | K6: B5 | L6: B5 | M6: B6 | N6: B6 | O6: B7 | P6: B7 | Q6: B8 | R6: B8 | S6: B9 | T6: B9 | U6: B10 | V6: B10 | W6: B11 | X6: B11 | Y6: B12 | Z6: B12 | AA6: B13 | AB6: B13 | AC6: B14 | AD6: B14 | AE6: B15 | AF6: B15 | AG6: B16 | AH6: B16 | AI6: B17 | AJ6: B17 | AK6: B18 | AL6: B18 | AM6: B19 | AN6: B19 | AO6: B20 | AP6: B20 | AQ6: B21 | AR6: B21
A7: 1 | B7: A1 | C7: =IF(data!C7="","",data!C7) | D7: =IF(C7="","",-C7) | E7: =IF(data!D7="","",data!D7) | F7: =IF(E7="","",-E7) | G7: =IF(data!E7="","",data!E7) | H7: =IF(G7="","",-G7) | I7: =IF(data!F7="","",data!F7) | J7: =IF(I7="","",-I7) | K7: =IF(data!G7="","",data!G7) | L7: =IF(K7="","",-K7) | M7: =IF(data!H7="","",data!H7) | N7: =IF(M7="","",-M7) | O7: =IF(data!I7="","",data!I7) | P7: =IF(O7="","",-O7) | Q7: =IF(data!J7="","",data!J7) | R7: =IF(Q7="","",-Q7) | S7: =IF(data!K7="","",data!K7) | T7: =IF(S7="","",-S7) | U7: =IF(data!L7="","",data!L7) | V7: =IF(U7="","",-U7) | W7: =IF(data!M7="","",data!M7) | X7: =IF(W7="","",-W7) | Y7: =IF(data!N7="","",data!N7) | Z7: =IF(Y7="","",-Y7) | AA7: =IF(data!O7="","",data!O7) | AB7: =IF(AA7="","",-AA7) | AC7: =IF(data!P7="","",data!P7) | AD7: =IF(AC7="","",-AC7) | AE7: =IF(data!Q7="","",data!Q7) | AF7: =IF(AE7="","",-AE7) | AG7: =IF(data!R7="","",data!R7) | AH7: =IF(AG7="","",-AG7) | AI7: =IF(data!S7="","",data!S7) | AJ7: =IF(AI7="","",-AI7) | AK7: =IF(data!T7="","",data!T7) | AL7: =IF(AK7="","",-AK7) | AM7: =IF(data!U7="","",data!U7) | AN7: =IF(AM7="","",-AM7) | AO7: =IF(data!V7="","",data!V7) | AP7: =IF(AO7="","",-AO7) | AQ7: =IF(data!W7="","",data!W7) | AR7: =IF(AQ7="","",-AQ7)
A8: 2 | B8: A2 | C8: =IF(data!C8="","",data!C8) | D8: =IF(C8="","",-C8) | E8: =IF(data!D8="","",data!D8) | F8: =IF(E8="","",-E8) | G8: =IF(data!E8="","",data!E8) | H8: =IF(G8="","",-G8) | I8: =IF(data!F8="","",data!F8) | J8: =IF(I8="","",-I8) | K8: =IF(data!G8="","",data!G8) | L8: =IF(K8="","",-K8) | M8: =IF(data!H8="","",data!H8) | N8: =IF(M8="","",-M8) | O8: =IF(data!I8="","",data!I8) | P8: =IF(O8="","",-O8) | Q8: =IF(data!J8="","",data!J8) | R8: =IF(Q8="","",-Q8) | S8: =IF(data!K8="","",data!K8) | T8: =IF(S8="","",-S8) | U8: =IF(data!L8="","",data!L8) | V8: =IF(U8="","",-U8) | W8: =IF(data!M8="","",data!M8) | X8: =IF(W8="","",-W8) | Y8: =IF(data!N8="","",data!N8) | Z8: =IF(Y8="","",-Y8) | AA8: =IF(data!O8="","",data!O8) | AB8: =IF(AA8="","",-AA8) | AC8: =IF(data!P8="","",data!P8) | AD8: =IF(AC8="","",-AC8) | AE8: =IF(data!Q8="","",data!Q8) | AF8: =IF(AE8="","",-AE8) | AG8: =IF(data!R8="","",data!R8) | AH8: =IF(AG8="","",-AG8) | AI8: =IF(data!S8="","",data!S8) | AJ8: =IF(AI8="","",-AI8) | AK8: =IF(data!T8="","",data!T8) | AL8: =IF(AK8="","",-AK8) | AM8: =IF(data!U8="","",data!U8) | AN8: =IF(AM8="","",-AM8) | AO8: =IF(data!V8="","",data!V8) | AP8: =IF(AO8="","",-AO8) | AQ8: =IF(data!W8="","",data!W8) | AR8: =IF(AQ8="","",-AQ8)
A9: 3 | B9: A3 | C9: =IF(data!C9="","",data!C9) | D9: =IF(C9="","",-C9) | E9: =IF(data!D9="","",data!D9) | F9: =IF(E9="","",-E9) | G9: =IF(data!E9="","",data!E9) | H9: =IF(G9="","",-G9) | I9: =IF(data!F9="","",data!F9) | J9: =IF(I9="","",-I9) | K9: =IF(data!G9="","",data!G9) | L9: =IF(K9="","",-K9) | M9: =IF(data!H9="","",data!H9) | N9: =IF(M9="","",-M9) | O9: =IF(data!I9="","",data!I9) | P9: =IF(O9="","",-O9) | Q9: =IF(data!J9="","",data!J9) | R9: =IF(Q9="","",-Q9) | S9: =IF(data!K9="","",data!K9) | T9: =IF(S9="","",-S9) | U9: =IF(data!L9="","",data!L9) | V9: =IF(U9="","",-U9) | W9: =IF(data!M9="","",data!M9) | X9: =IF(W9="","",-W9) | Y9: =IF(data!N9="","",data!N9) | Z9: =IF(Y9="","",-Y9) | AA9: =IF(data!O9="","",data!O9) | AB9: =IF(AA9="","",-AA9) | AC9: =IF(data!P9="","",data!P9) | AD9: =IF(AC9="","",-AC9) | AE9: =IF(data!Q9="","",data!Q9) | AF9: =IF(AE9="","",-AE9) | AG9: =IF(data!R9="","",data!R9) | AH9: =IF(AG9="","",-AG9) | AI9: =IF(data!S9="","",data!S9) | AJ9: =IF(AI9="","",-AI9) | AK9: =IF(data!T9="","",data!T9) | AL9: =IF(AK9="","",-AK9) | AM9: =IF(data!U9="","",data!U9) | AN9: =IF(AM9="","",-AM9) | AO9: =IF(data!V9="","",data!V9) | AP9: =IF(AO9="","",-AO9) | AQ9: =IF(data!W9="","",data!W9) | AR9: =IF(AQ9="","",-AQ9)
A10: 4 | B10: A4 | C10: =IF(data!C10="","",data!C10) | D10: =IF(C10="","",-C10) | E10: =IF(data!D10="","",data!D10) | F10: =IF(E10="","",-E10) | G10: =IF(data!E10="","",data!E10) | H10: =IF(G10="","",-G10) | I10: =IF(data!F10="","",data!F10) | J10: =IF(I10="","",-I10) | K10: =IF(data!G10="","",data!G10) | L10: =IF(K10="","",-K10) | M10: =IF(data!H10="","",data!H10) | N10: =IF(M10="","",-M10) | O10: =IF(data!I10="","",data!I10) | P10: =IF(O10="","",-O10) | Q10: =IF(data!J10="","",data!J10) | R10: =IF(Q10="","",-Q10) | S10: =IF(data!K10="","",data!K10) | T10: =IF(S10="","",-S10) | U10: =IF(data!L10="","",data!L10) | V10: =IF(U10="","",-U10) | W10: =IF(data!M10="","",data!M10) | X10: =IF(W10="","",-W10) | Y10: =IF(data!N10="","",data!N10) | Z10: =IF(Y10="","",-Y10) | AA10: =IF(data!O10="","",data!O10) | AB10: =IF(AA10="","",-AA10) | AC10: =IF(data!P10="","",data!P10) | AD10: =IF(AC10="","",-AC10) | AE10: =IF(data!Q10="","",data!Q10) | AF10: =IF(AE10="","",-AE10) | AG10: =IF(data!R10="","",data!R10) | AH10: =IF(AG10="","",-AG10) | AI10: =IF(data!S10="","",data!S10) | AJ10: =IF(AI10="","",-AI10) | AK10: =IF(data!T10="","",data!T10) | AL10: =IF(AK10="","",-AK10) | AM10: =IF(data!U10="","",data!U10) | AN10: =IF(AM10="","",-AM10) | AO10: =IF(data!V10="","",data!V10) | AP10: =IF(AO10="","",-AO10) | AQ10: =IF(data!W10="","",data!W10) | AR10: =IF(AQ10="","",-AQ10)
A11: 5 | B11: A5 | C11: =IF(data!C11="","",data!C11) | D11: =IF(C11="","",-C11) | E11: =IF(data!D11="","",data!D11) | F11: =IF(E11="","",-E11) | G11: =IF(data!E11="","",data!E11) | H11: =IF(G11="","",-G11) | I11: =IF(data!F11="","",data!F11) | J11: =IF(I11="","",-I11) | K11: =IF(data!G11="","",data!G11) | L11: =IF(K11="","",-K11) | M11: =IF(data!H11="","",data!H11) | N11: =IF(M11="","",-M11) | O11: =IF(data!I11="","",data!I11) | P11: =IF(O11="","",-O11) | Q11: =IF(data!J11="","",data!J11) | R11: =IF(Q11="","",-Q11) | S11: =IF(data!K11="","",data!K11) | T11: =IF(S11="","",-S11) | U11: =IF(data!L11="","",data!L11) | V11: =IF(U11="","",-U11) | W11: =IF(data!M11="","",data!M11) | X11: =IF(W11="","",-W11) | Y11: =IF(data!N11="","",data!N11) | Z11: =IF(Y11="","",-Y11) | AA11: =IF(data!O11="","",data!O11) | AB11: =IF(AA11="","",-AA11) | AC11: =IF(data!P11="","",data!P11) | AD11: =IF(AC11="","",-AC11) | AE11: =IF(data!Q11="","",data!Q11) | AF11: =IF(AE11="","",-AE11) | AG11: =IF(data!R11="","",data!R11) | AH11: =IF(AG11="","",-AG11) | AI11: =IF(data!S11="","",data!S11) | AJ11: =IF(AI11="","",-AI11) | AK11: =IF(data!T11="","",data!T11) | AL11: =IF(AK11="","",-AK11) | AM11: =IF(data!U11="","",data!U11) | AN11: =IF(AM11="","",-AM11) | AO11: =IF(data!V11="","",data!V11) | AP11: =IF(AO11="","",-AO11) | AQ11: =IF(data!W11="","",data!W11) | AR11: =IF(AQ11="","",-AQ11)
A12: 6 | B12: A6 | C12: =IF(data!C12="","",data!C12) | D12: =IF(C12="","",-C12) | E12: =IF(data!D12="","",data!D12) | F12: =IF(E12="","",-E12) | G12: =IF(data!E12="","",data!E12) | H12: =IF(G12="","",-G12) | I12: =IF(data!F12="","",data!F12) | J12: =IF(I12="","",-I12) | K12: =IF(data!G12="","",data!G12) | L12: =IF(K12="","",-K12) | M12: =IF(data!H12="","",data!H12) | N12: =IF(M12="","",-M12) | O12: =IF(data!I12="","",data!I12) | P12: =IF(O12="","",-O12) | Q12: =IF(data!J12="","",data!J12) | R12: =IF(Q12="","",-Q12) | S12: =IF(data!K12="","",data!K12) | T12: =IF(S12="","",-S12) | U12: =IF(data!L12="","",data!L12) | V12: =IF(U12="","",-U12) | W12: =IF(data!M12="","",data!M12) | X12: =IF(W12="","",-W12) | Y12: =IF(data!N12="","",data!N12) | Z12: =IF(Y12="","",-Y12) | AA12: =IF(data!O12="","",data!O12) | AB12: =IF(AA12="","",-AA12) | AC12: =IF(data!P12="","",data!P12) | AD12: =IF(AC12="","",-AC12) | AE12: =IF(data!Q12="","",data!Q12) | AF12: =IF(AE12="","",-AE12) | AG12: =IF(data!R12="","",data!R12) | AH12: =IF(AG12="","",-AG12) | AI12: =IF(data!S12="","",data!S12) | AJ12: =IF(AI12="","",-AI12) | AK12: =IF(data!T12="","",data!T12) | AL12: =IF(AK12="","",-AK12) | AM12: =IF(data!U12="","",data!U12) | AN12: =IF(AM12="","",-AM12) | AO12: =IF(data!V12="","",data!V12) | AP12: =IF(AO12="","",-AO12) | AQ12: =IF(data!W12="","",data!W12) | AR12: =IF(AQ12="","",-AQ12)
A13: 7 | B13: A7 | C13: =IF(data!C13="","",data!C13) | D13: =IF(C13="","",-C13) | E13: =IF(data!D13="","",data!D13) | F13: =IF(E13="","",-E13) | G13: =IF(data!E13="","",data!E13) | H13: =IF(G13="","",-G13) | I13: =IF(data!F13="","",data!F13) | J13: =IF(I13="","",-I13) | K13: =IF(data!G13="","",data!G13) | L13: =IF(K13="","",-K13) | M13: =IF(data!H13="","",data!H13) | N13: =IF(M13="","",-M13) | O13: =IF(data!I13="","",data!I13) | P13: =IF(O13="","",-O13) | Q13: =IF(data!J13="","",data!J13) | R13: =IF(Q13="","",-Q13) | S13: =IF(data!K13="","",data!K13) | T13: =IF(S13="","",-S13) | U13: =IF(data!L13="","",data!L13) | V13: =IF(U13="","",-U13) | W13: =IF(data!M13="","",data!M13) | X13: =IF(W13="","",-W13) | Y13: =IF(data!N13="","",data!N13) | Z13: =IF(Y13="","",-Y13) | AA13: =IF(data!O13="","",data!O13) | AB13: =IF(AA13="","",-AA13) | AC13: =IF(data!P13="","",data!P13) | AD13: =IF(AC13="","",-AC13) | AE13: =IF(data!Q13="","",data!Q13) | AF13: =IF(AE13="","",-AE13) | AG13: =IF(data!R13="","",data!R13) | AH13: =IF(AG13="","",-AG13) | AI13: =IF(data!S13="","",data!S13) | AJ13: =IF(AI13="","",-AI13) | AK13: =IF(data!T13="","",data!T13) | AL13: =IF(AK13="","",-AK13) | AM13: =IF(data!U13="","",data!U13) | AN13: =IF(AM13="","",-AM13) | AO13: =IF(data!V13="","",data!V13) | AP13: =IF(AO13="","",-AO13) | AQ13: =IF(data!W13="","",data!W13) | AR13: =IF(AQ13="","",-AQ13)
A14: 8 | B14: A8 | C14: =IF(data!C14="","",data!C14) | D14: =IF(C14="","",-C14) | E14: =IF(data!D14="","",data!D14) | F14: =IF(E14="","",-E14) | G14: =IF(data!E14="","",data!E14) | H14: =IF(G14="","",-G14) | I14: =IF(data!F14="","",data!F14) | J14: =IF(I14="","",-I14) | K14: =IF(data!G14="","",data!G14) | L14: =IF(K14="","",-K14) | M14: =IF(data!H14="","",data!H14) | N14: =IF(M14="","",-M14) | O14: =IF(data!I14="","",data!I14) | P14: =IF(O14="","",-O14) | Q14: =IF(data!J14="","",data!J14) | R14: =IF(Q14="","",-Q14) | S14: =IF(data!K14="","",data!K14) | T14: =IF(S14="","",-S14) | U14: =IF(data!L14="","",data!L14) | V14: =IF(U14="","",-U14) | W14: =IF(data!M14="","",data!M14) | X14: =IF(W14="","",-W14) | Y14: =IF(data!N14="","",data!N14) | Z14: =IF(Y14="","",-Y14) | AA14: =IF(data!O14="","",data!O14) | AB14: =IF(AA14="","",-AA14) | AC14: =IF(data!P14="","",data!P14) | AD14: =IF(AC14="","",-AC14) | AE14: =IF(data!Q14="","",data!Q14) | AF14: =IF(AE14="","",-AE14) | AG14: =IF(data!R14="","",data!R14) | AH14: =IF(AG14="","",-AG14) | AI14: =IF(data!S14="","",data!S14) | AJ14: =IF(AI14="","",-AI14) | AK14: =IF(data!T14="","",data!T14) | AL14: =IF(AK14="","",-AK14) | AM14: =IF(data!U14="","",data!U14) | AN14: =IF(AM14="","",-AM14) | AO14: =IF(data!V14="","",data!V14) | AP14: =IF(AO14="","",-AO14) | AQ14: =IF(data!W14="","",data!W14) | AR14: =IF(AQ14="","",-AQ14)
A15: 9 | B15: A9 | C15: =IF(data!C15="","",data!C15) | D15: =IF(C15="","",-C15) | E15: =IF(data!D15="","",data!D15) | F15: =IF(E15="","",-E15) | G15: =IF(data!E15="","",data!E15) | H15: =IF(G15="","",-G15) | I15: =IF(data!F15="","",data!F15) | J15: =IF(I15="","",-I15) | K15: =IF(data!G15="","",data!G15) | L15: =IF(K15="","",-K15) | M15: =IF(data!H15="","",data!H15) | N15: =IF(M15="","",-M15) | O15: =IF(data!I15="","",data!I15) | P15: =IF(O15="","",-O15) | Q15: =IF(data!J15="","",data!J15) | R15: =IF(Q15="","",-Q15) | S15: =IF(data!K15="","",data!K15) | T15: =IF(S15="","",-S15) | U15: =IF(data!L15="","",data!L15) | V15: =IF(U15="","",-U15) | W15: =IF(data!M15="","",data!M15) | X15: =IF(W15="","",-W15) | Y15: =IF(data!N15="","",data!N15) | Z15: =IF(Y15="","",-Y15) | AA15: =IF(data!O15="","",data!O15) | AB15: =IF(AA15="","",-AA15) | AC15: =IF(data!P15="","",data!P15) | AD15: =IF(AC15="","",-AC15) | AE15: =IF(data!Q15="","",data!Q15) | AF15: =IF(AE15="","",-AE15) | AG15: =IF(data!R15="","",data!R15) | AH15: =IF(AG15="","",-AG15) | AI15: =IF(data!S15="","",data!S15) | AJ15: =IF(AI15="","",-AI15) | AK15: =IF(data!T15="","",data!T15) | AL15: =IF(AK15="","",-AK15) | AM15: =IF(data!U15="","",data!U15) | AN15: =IF(AM15="","",-AM15) | AO15: =IF(data!V15="","",data!V15) | AP15: =IF(AO15="","",-AO15) | AQ15: =IF(data!W15="","",data!W15) | AR15: =IF(AQ15="","",-AQ15)
A16: 10 | B16: A10 | C16: =IF(data!C16="","",data!C16) | D16: =IF(C16="","",-C16) | E16: =IF(data!D16="","",data!D16) | F16: =IF(E16="","",-E16) | G16: =IF(data!E16="","",data!E16) | H16: =IF(G16="","",-G16) | I16: =IF(data!F16="","",data!F16) | J16: =IF(I16="","",-I16) | K16: =IF(data!G16="","",data!G16) | L16: =IF(K16="","",-K16) | M16: =IF(data!H16="","",data!H16) | N16: =IF(M16="","",-M16) | O16: =IF(data!I16="","",data!I16) | P16: =IF(O16="","",-O16) | Q16: =IF(data!J16="","",data!J16) | R16: =IF(Q16="","",-Q16) | S16: =IF(data!K16="","",data!K16) | T16: =IF(S16="","",-S16) | U16: =IF(data!L16="","",data!L16) | V16: =IF(U16="","",-U16) | W16: =IF(data!M16="","",data!M16) | X16: =IF(W16="","",-W16) | Y16: =IF(data!N16="","",data!N16) | Z16: =IF(Y16="","",-Y16) | AA16: =IF(data!O16="","",data!O16) | AB16: =IF(AA16="","",-AA16) | AC16: =IF(data!P16="","",data!P16) | AD16: =IF(AC16="","",-AC16) | AE16: =IF(data!Q16="","",data!Q16) | AF16: =IF(AE16="","",-AE16) | AG16: =IF(data!R16="","",data!R16) | AH16: =IF(AG16="","",-AG16) | AI16: =IF(data!S16="","",data!S16) | AJ16: =IF(AI16="","",-AI16) | AK16: =IF(data!T16="","",data!T16) | AL16: =IF(AK16="","",-AK16) | AM16: =IF(data!U16="","",data!U16) | AN16: =IF(AM16="","",-AM16) | AO16: =IF(data!V16="","",data!V16) | AP16: =IF(AO16="","",-AO16) | AQ16: =IF(data!W16="","",data!W16) | AR16: =IF(AQ16="","",-AQ16)
A17: 11 | B17: A11 | C17: =IF(data!C17="","",data!C17) | D17: =IF(C17="","",-C17) | E17: =IF(data!D17="","",data!D17) | F17: =IF(E17="","",-E17) | G17: =IF(data!E17="","",data!E17) | H17: =IF(G17="","",-G17) | I17: =IF(data!F17="","",data!F17) | J17: =IF(I17="","",-I17) | K17: =IF(data!G17="","",data!G17) | L17: =IF(K17="","",-K17) | M17: =IF(data!H17="","",data!H17) | N17: =IF(M17="","",-M17) | O17: =IF(data!I17="","",data!I17) | P17: =IF(O17="","",-O17) | Q17: =IF(data!J17="","",data!J17) | R17: =IF(Q17="","",-Q17) | S17: =IF(data!K17="","",data!K17) | T17: =IF(S17="","",-S17) | U17: =IF(data!L17="","",data!L17) | V17: =IF(U17="","",-U17) | W17: =IF(data!M17="","",data!M17) | X17: =IF(W17="","",-W17) | Y17: =IF(data!N17="","",data!N17) | Z17: =IF(Y17="","",-Y17) | AA17: =IF(data!O17="","",data!O17) | AB17: =IF(AA17="","",-AA17) | AC17: =IF(data!P17="","",data!P17) | AD17: =IF(AC17="","",-AC17) | AE17: =IF(data!Q17="","",data!Q17) | AF17: =IF(AE17="","",-AE17) | AG17: =IF(data!R17="","",data!R17) | AH17: =IF(AG17="","",-AG17) | AI17: =IF(data!S17="","",data!S17) | AJ17: =IF(AI17="","",-AI17) | AK17: =IF(data!T17="","",data!T17) | AL17: =IF(AK17="","",-AK17) | AM17: =IF(data!U17="","",data!U17) | AN17: =IF(AM17="","",-AM17) | AO17: =IF(data!V17="","",data!V17) | AP17: =IF(AO17="","",-AO17) | AQ17: =IF(data!W17="","",data!W17) | AR17: =IF(AQ17="","",-AQ17)
A18: 12 | B18: A12 | C18: =IF(data!C18="","",data!C18) | D18: =IF(C18="","",-C18) | E18: =IF(data!D18="","",data!D18) | F18: =IF(E18="","",-E18) | G18: =IF(data!E18="","",data!E18) | H18: =IF(G18="","",-G18) | I18: =IF(data!F18="","",data!F18) | J18: =IF(I18="","",-I18) | K18: =IF(data!G18="","",data!G18) | L18: =IF(K18="","",-K18) | M18: =IF(data!H18="","",data!H18) | N18: =IF(M18="","",-M18) | O18: =IF(data!I18="","",data!I18) | P18: =IF(O18="","",-O18) | Q18: =IF(data!J18="","",data!J18) | R18: =IF(Q18="","",-Q18) | S18: =IF(data!K18="","",data!K18) | T18: =IF(S18="","",-S18) | U18: =IF(data!L18="","",data!L18) | V18: =IF(U18="","",-U18) | W18: =IF(data!M18="","",data!M18) | X18: =IF(W18="","",-W18) | Y18: =IF(data!N18="","",data!N18) | Z18: =IF(Y18="","",-Y18) | AA18: =IF(data!O18="","",data!O18) | AB18: =IF(AA18="","",-AA18) | AC18: =IF(data!P18="","",data!P18) | AD18: =IF(AC18="","",-AC18) | AE18: =IF(data!Q18="","",data!Q18) | AF18: =IF(AE18="","",-AE18) | AG18: =IF(data!R18="","",data!R18) | AH18: =IF(AG18="","",-AG18) | AI18: =IF(data!S18="","",data!S18) | AJ18: =IF(AI18="","",-AI18) | AK18: =IF(data!T18="","",data!T18) | AL18: =IF(AK18="","",-AK18) | AM18: =IF(data!U18="","",data!U18) | AN18: =IF(AM18="","",-AM18) | AO18: =IF(data!V18="","",data!V18) | AP18: =IF(AO18="","",-AO18) | AQ18: =IF(data!W18="","",data!W18) | AR18: =IF(AQ18="","",-AQ18)
... A27: 21 | B27: A21 | C27: =IF(data!C27="","",data!C27) | D27: =IF(C27="","",-C27) | E27: =IF(data!D27="","",data!D27) | F27: =IF(E27="","",-E27) | G27: =IF(data!E27="","",data!E27) | H27: =IF(G27="","",-G27) | I27: =IF(data!F27="","",data!F27) | J27: =IF(I27="","",-I27) | K27: =IF(data!G27="","",data!G27) | L27: =IF(K27="","",-K27) | M27: =IF(data!H27="","",data!H27) | N27: =IF(M27="","",-M27) | O27: =IF(data!I27="","",data!I27) | P27: =IF(O27="","",-O27) | Q27: =IF(data!J27="","",data!J27) | R27: =IF(Q27="","",-Q27) | S27: =IF(data!K27="","",data!K27) | T27: =IF(S27="","",-S27) | U27: =IF(data!L27="","",data!L27) | V27: =IF(U27="","",-U27) | W27: =IF(data!M27="","",data!M27) | X27: =IF(W27="","",-W27) | Y27: =IF(data!N27="","",data!N27) | Z27: =IF(Y27="","",-Y27) | AA27: =IF(data!O27="","",data!O27) | AB27: =IF(AA27="","",-AA27) | AC27: =IF(data!P27="","",data!P27) | AD27: =IF(AC27="","",-AC27) | AE27: =IF(data!Q27="","",data!Q27) | AF27: =IF(AE27="","",-AE27) | AG27: =IF(data!R27="","",data!R27) | AH27: =IF(AG27="","",-AG27) | AI27: =IF(data!S27="","",data!S27) | AJ27: =IF(AI27="","",-AI27) | AK27: =IF(data!T27="","",data!T27) | AL27: =IF(AK27="","",-AK27) | AM27: =IF(data!U27="","",data!U27) | AN27: =IF(AM27="","",-AM27) | AO27: =IF(data!V27="","",data!V27) | AP27: =IF(AO27="","",-AO27) | AQ27: =IF(data!W27="","",data!W27) | AR27: =IF(AQ27="","",-AQ27)

Sheet maximin
G1: MAXIMIN
B2: The Maximin moves are marked in red
C4: the matrix
C5: 1 | D5: 1 | E5: 2 | F5: 2 | G5: 3 | H5: 3 | I5: 4 | J5: 4 | K5: 5 | L5: 5 | M5: 6 | N5: 6 | O5: 7 | P5: 7 | Q5: 8 | R5: 8 | S5: 9 | T5: 9 | U5: 10 | V5: 10 | W5: 11 | X5: 11 | Y5: 12 | Z5: 12 | AA5: 13 | AB5: 13 | AC5: 14 | AD5: 14 | AE5: 15 | AF5: 15 | AG5: 16 | AH5: 16 | AI5: 17 | AJ5: 17 | AK5: 18 | AL5: 18 | AM5: 19 | AN5: 19 | AO5: 20 | AP5: 20 | AQ5: 21 | AR5: 21
C6: B1 | D6: B1 | E6: B2 | F6: B2 | G6: B3 | H6: B3 | I6: B4 | J6: B4 | K6: B5 | L6: B5 | M6: B6 | N6: B6 | O6: B7 | P6: B7 | Q6: B8 | R6: B8 | S6: B9 | T6: B9 | U6: B10 | V6: B10 | W6: B11 | X6: B11 | Y6: B12 | Z6: B12 | AA6: B13 | AB6: B13 | AC6: B14 | AD6: B14 | AE6: B15 | AF6: B15 | AG6: B16 | AH6: B16 | AI6: B17 | AJ6: B17 | AK6: B18 | AL6: B18 | AM6: B19 | AN6: B19 | AO6: B20 | AP6: B20 | AQ6: B21 | AR6: B21
A7: 1 | B7: A1 | C7: =IF('non-zero-sum'!C7="","",'non-zero-sum'!C7) | D7: =IF('non-zero-sum'!D7="","",'non-zero-sum'!D7) | E7: =IF('non-zero-sum'!E7="","",'non-zero-sum'!E7) | F7: =IF('non-zero-sum'!F7="","",'non-zero-sum'!F7) | G7: =IF('non-zero-sum'!G7="","",'non-zero-sum'!G7) | H7: =IF('non-zero-sum'!H7="","",'non-zero-sum'!H7) | I7: =IF('non-zero-sum'!I7="","",'non-zero-sum'!I7) | J7: =IF('non-zero-sum'!J7="","",'non-zero-sum'!J7) | ... AR7: =IF('non-zero-sum'!AR7="","",'non-zero-sum'!AR7) | AS7: =IF(COUNTIF(C7:AR7,">-1000")>0,MIN(C7,E7,G7,I7,K7,M7,O7,Q7,S7,U7,W7,Y7,AA7,AC7,AE7,AG7,AI7,AK7,AM7,AO7,AQ7),-1000) -> -1000
A8: 2 | B8: A2 | C8: =IF('non-zero-sum'!C8="","",'non-zero-sum'!C8) | D8: =IF('non-zero-sum'!D8="","",'non-zero-sum'!D8) | E8: =IF('non-zero-sum'!E8="","",'non-zero-sum'!E8) | F8: =IF('non-zero-sum'!F8="","",'non-zero-sum'!F8) | G8: =IF('non-zero-sum'!G8="","",'non-zero-sum'!G8) | H8: =IF('non-zero-sum'!H8="","",'non-zero-sum'!H8) | I8: =IF('non-zero-sum'!I8="","",'non-zero-sum'!I8) | J8: =IF('non-zero-sum'!J8="","",'non-zero-sum'!J8) | ... AR8: =IF('non-zero-sum'!AR8="","",'non-zero-sum'!AR8) | AS8: =IF(COUNTIF(C8:AR8,">-1000")>0,MIN(C8,E8,G8,I8,K8,M8,O8,Q8,S8,U8,W8,Y8,AA8,AC8,AE8,AG8,AI8,AK8,AM8,AO8,AQ8),-1000) -> -1000
A9: 3 | B9: A3 | C9: =IF('non-zero-sum'!C9="","",'non-zero-sum'!C9) | D9: =IF('non-zero-sum'!D9="","",'non-zero-sum'!D9) | E9: =IF('non-zero-sum'!E9="","",'non-zero-sum'!E9) | F9: =IF('non-zero-sum'!F9="","",'non-zero-sum'!F9) | G9: =IF('non-zero-sum'!G9="","",'non-zero-sum'!G9) | H9: =IF('non-zero-sum'!H9="","",'non-zero-sum'!H9) | I9: =IF('non-zero-sum'!I9="","",'non-zero-sum'!I9) | J9: =IF('non-zero-sum'!J9="","",'non-zero-sum'!J9) | ... AR9: =IF('non-zero-sum'!AR9="","",'non-zero-sum'!AR9) | AS9: =IF(COUNTIF(C9:AR9,">-1000")>0,MIN(C9,E9,G9,I9,K9,M9,O9,Q9,S9,U9,W9,Y9,AA9,AC9,AE9,AG9,AI9,AK9,AM9,AO9,AQ9),-1000) -> -1000
A10: 4 | B10: A4 | C10: =IF('non-zero-sum'!C10="","",'non-zero-sum'!C10) | D10: =IF('non-zero-sum'!D10="","",'non-zero-sum'!D10) | E10: =IF('non-zero-sum'!E10="","",'non-zero-sum'!E10) | F10: =IF('non-zero-sum'!F10="","",'non-zero-sum'!F10) | G10: =IF('non-zero-sum'!G10="","",'non-zero-sum'!G10) | H10: =IF('non-zero-sum'!H10="","",'non-zero-sum'!H10) | I10: =IF('non-zero-sum'!I10="","",'non-zero-sum'!I10) | J10: =IF('non-zero-sum'!J10="","",'non-zero-sum'!J10) | ... AR10: =IF('non-zero-sum'!AR10="","",'non-zero-sum'!AR10) | AS10: =IF(COUNTIF(C10:AR10,">-1000")>0,MIN(C10,E10,G10,I10,K10,M10,O10,Q10,S10,U10,W10,Y10,AA10,AC10,AE10,AG10,AI10,AK10,AM10,AO10,AQ10),-1000) -> -1000
A11: 5 | B11: A5 | C11: =IF('non-zero-sum'!C11="","",'non-zero-sum'!C11) | D11: =IF('non-zero-sum'!D11="","",'non-zero-sum'!D11) | E11: =IF('non-zero-sum'!E11="","",'non-zero-sum'!E11) | F11: =IF('non-zero-sum'!F11="","",'non-zero-sum'!F11) | G11: =IF('non-zero-sum'!G11="","",'non-zero-sum'!G11) | H11: =IF('non-zero-sum'!H11="","",'non-zero-sum'!H11) | I11: =IF('non-zero-sum'!I11="","",'non-zero-sum'!I11) | J11: =IF('non-zero-sum'!J11="","",'non-zero-sum'!J11) | ... AR11: =IF('non-zero-sum'!AR11="","",'non-zero-sum'!AR11) | AS11: =IF(COUNTIF(C11:AR11,">-1000")>0,MIN(C11,E11,G11,I11,K11,M11,O11,Q11,S11,U11,W11,Y11,AA11,AC11,AE11,AG11,AI11,AK11,AM11,AO11,AQ11),-1000) -> -1000
A12: 6 | B12: A6 | C12: =IF('non-zero-sum'!C12="","",'non-zero-sum'!C12) | D12: =IF('non-zero-sum'!D12="","",'non-zero-sum'!D12) | E12: =IF('non-zero-sum'!E12="","",'non-zero-sum'!E12) | F12: =IF('non-zero-sum'!F12="","",'non-zero-sum'!F12) | G12: =IF('non-zero-sum'!G12="","",'non-zero-sum'!G12) | H12: =IF('non-zero-sum'!H12="","",'non-zero-sum'!H12) | I12: =IF('non-zero-sum'!I12="","",'non-zero-sum'!I12) | J12: =IF('non-zero-sum'!J12="","",'non-zero-sum'!J12) | ... AR12: =IF('non-zero-sum'!AR12="","",'non-zero-sum'!AR12) | AS12: =IF(COUNTIF(C12:AR12,">-1000")>0,MIN(C12,E12,G12,I12,K12,M12,O12,Q12,S12,U12,W12,Y12,AA12,AC12,AE12,AG12,AI12,AK12,AM12,AO12,AQ12),-1000) -> -1000
A13: 7 | B13: A7 | C13: =IF('non-zero-sum'!C13="","",'non-zero-sum'!C13) | D13: =IF('non-zero-sum'!D13="","",'non-zero-sum'!D13) | E13: =IF('non-zero-sum'!E13="","",'non-zero-sum'!E13) | F13: =IF('non-zero-sum'!F13="","",'non-zero-sum'!F13) | G13: =IF('non-zero-sum'!G13="","",'non-zero-sum'!G13) | H13: =IF('non-zero-sum'!H13="","",'non-zero-sum'!H13) | I13: =IF('non-zero-sum'!I13="","",'non-zero-sum'!I13) | J13: =IF('non-zero-sum'!J13="","",'non-zero-sum'!J13) | ... AR13: =IF('non-zero-sum'!AR13="","",'non-zero-sum'!AR13) | AS13: =IF(COUNTIF(C13:AR13,">-1000")>0,MIN(C13,E13,G13,I13,K13,M13,O13,Q13,S13,U13,W13,Y13,AA13,AC13,AE13,AG13,AI13,AK13,AM13,AO13,AQ13),-1000) -> -1000
A14: 8 | B14: A8 | C14: =IF('non-zero-sum'!C14="","",'non-zero-sum'!C14) | D14: =IF('non-zero-sum'!D14="","",'non-zero-sum'!D14) | E14: =IF('non-zero-sum'!E14="","",'non-zero-sum'!E14) | F14: =IF('non-zero-sum'!F14="","",'non-zero-sum'!F14) | G14: =IF('non-zero-sum'!G14="","",'non-zero-sum'!G14) | H14: =IF('non-zero-sum'!H14="","",'non-zero-sum'!H14) | I14: =IF('non-zero-sum'!I14="","",'non-zero-sum'!I14) | J14: =IF('non-zero-sum'!J14="","",'non-zero-sum'!J14) | ... AR14: =IF('non-zero-sum'!AR14="","",'non-zero-sum'!AR14) | AS14: =IF(COUNTIF(C14:AR14,">-1000")>0,MIN(C14,E14,G14,I14,K14,M14,O14,Q14,S14,U14,W14,Y14,AA14,AC14,AE14,AG14,AI14,AK14,AM14,AO14,AQ14),-1000) -> -1000
A15: 9 | B15: A9 | C15: =IF('non-zero-sum'!C15="","",'non-zero-sum'!C15) | D15: =IF('non-zero-sum'!D15="","",'non-zero-sum'!D15) | E15: =IF('non-zero-sum'!E15="","",'non-zero-sum'!E15) | F15: =IF('non-zero-sum'!F15="","",'non-zero-sum'!F15) | G15: =IF('non-zero-sum'!G15="","",'non-zero-sum'!G15) | H15: =IF('non-zero-sum'!H15="","",'non-zero-sum'!H15) | I15: =IF('non-zero-sum'!I15="","",'non-zero-sum'!I15) | J15: =IF('non-zero-sum'!J15="","",'non-zero-sum'!J15) | ... AR15: =IF('non-zero-sum'!AR15="","",'non-zero-sum'!AR15) | AS15: =IF(COUNTIF(C15:AR15,">-1000")>0,MIN(C15,E15,G15,I15,K15,M15,O15,Q15,S15,U15,W15,Y15,AA15,AC15,AE15,AG15,AI15,AK15,AM15,AO15,AQ15),-1000) -> -1000
A16: 10 | B16: A10 | C16: =IF('non-zero-sum'!C16="","",'non-zero-sum'!C16) | D16: =IF('non-zero-sum'!D16="","",'non-zero-sum'!D16) | E16: =IF('non-zero-sum'!E16="","",'non-zero-sum'!E16) | F16: =IF('non-zero-sum'!F16="","",'non-zero-sum'!F16) | G16: =IF('non-zero-sum'!G16="","",'non-zero-sum'!G16) | H16: =IF('non-zero-sum'!H16="","",'non-zero-sum'!H16) | I16: =IF('non-zero-sum'!I16="","",'non-zero-sum'!I16) | J16: =IF('non-zero-sum'!J16="","",'non-zero-sum'!J16) | ... AR16: =IF('non-zero-sum'!AR16="","",'non-zero-sum'!AR16) | AS16: =IF(COUNTIF(C16:AR16,">-1000")>0,MIN(C16,E16,G16,I16,K16,M16,O16,Q16,S16,U16,W16,Y16,AA16,AC16,AE16,AG16,AI16,AK16,AM16,AO16,AQ16),-1000) -> -1000
A17: 11 | B17: A11 | C17: =IF('non-zero-sum'!C17="","",'non-zero-sum'!C17) | D17: =IF('non-zero-sum'!D17="","",'non-zero-sum'!D17) | E17: =IF('non-zero-sum'!E17="","",'non-zero-sum'!E17) | F17: =IF('non-zero-sum'!F17="","",'non-zero-sum'!F17) | G17: =IF('non-zero-sum'!G17="","",'non-zero-sum'!G17) | H17: =IF('non-zero-sum'!H17="","",'non-zero-sum'!H17) | I17: =IF('non-zero-sum'!I17="","",'non-zero-sum'!I17) | J17: =IF('non-zero-sum'!J17="","",'non-zero-sum'!J17) | ... AR17: =IF('non-zero-sum'!AR17="","",'non-zero-sum'!AR17) | AS17: =IF(COUNTIF(C17:AR17,">-1000")>0,MIN(C17,E17,G17,I17,K17,M17,O17,Q17,S17,U17,W17,Y17,AA17,AC17,AE17,AG17,AI17,AK17,AM17,AO17,AQ17),-1000) -> -1000
A18: 12 | B18: A12 | C18: =IF('non-zero-sum'!C18="","",'non-zero-sum'!C18) | D18: =IF('non-zero-sum'!D18="","",'non-zero-sum'!D18) | E18: =IF('non-zero-sum'!E18="","",'non-zero-sum'!E18) | F18: =IF('non-zero-sum'!F18="","",'non-zero-sum'!F18) | G18: =IF('non-zero-sum'!G18="","",'non-zero-sum'!G18) | H18: =IF('non-zero-sum'!H18="","",'non-zero-sum'!H18) | I18: =IF('non-zero-sum'!I18="","",'non-zero-sum'!I18) | J18: =IF('non-zero-sum'!J18="","",'non-zero-sum'!J18) | ... AR18: =IF('non-zero-sum'!AR18="","",'non-zero-sum'!AR18) | AS18: =IF(COUNTIF(C18:AR18,">-1000")>0,MIN(C18,E18,G18,I18,K18,M18,O18,Q18,S18,U18,W18,Y18,AA18,AC18,AE18,AG18,AI18,AK18,AM18,AO18,AQ18),-1000) -> -1000
... A26: 20 | B26: A20 | C26: =IF('non-zero-sum'!C26="","",'non-zero-sum'!C26) | D26: =IF('non-zero-sum'!D26="","",'non-zero-sum'!D26) | E26: =IF('non-zero-sum'!E26="","",'non-zero-sum'!E26) | F26: =IF('non-zero-sum'!F26="","",'non-zero-sum'!F26) | G26: =IF('non-zero-sum'!G26="","",'non-zero-sum'!G26) | H26: =IF('non-zero-sum'!H26="","",'non-zero-sum'!H26) | I26: =IF('non-zero-sum'!I26="","",'non-zero-sum'!I26) | J26: =IF('non-zero-sum'!J26="","",'non-zero-sum'!J26) | ... AR26: =IF('non-zero-sum'!AR26="","",'non-zero-sum'!AR26) | AS26: =IF(COUNTIF(C26:AR26,">-1000")>0,MIN(C26,E26,G26,I26,K26,M26,O26,Q26,S26,U26,W26,Y26,AA26,AC26,AE26,AG26,AI26,AK26,AM26,AO26,AQ26),-1000) -> -1000
A27: 21 | B27: A21 | C27: =IF('non-zero-sum'!C27="","",'non-zero-sum'!C27) | D27: =IF('non-zero-sum'!D27="","",'non-zero-sum'!D27) | E27: =IF('non-zero-sum'!E27="","",'non-zero-sum'!E27) | F27: =IF('non-zero-sum'!F27="","",'non-zero-sum'!F27) | G27: =IF('non-zero-sum'!G27="","",'non-zero-sum'!G27) | H27: =IF('non-zero-sum'!H27="","",'non-zero-sum'!H27) | I27: =IF('non-zero-sum'!I27="","",'non-zero-sum'!I27) | J27: =IF('non-zero-sum'!J27="","",'non-zero-sum'!J27) | ... AR27: =IF('non-zero-sum'!AR27="","",'non-zero-sum'!AR27) | AS27: =IF(COUNTIF(C27:AR27,">-1000")>0,MIN(C27,E27,G27,I27,K27,M27,O27,Q27,S27,U27,W27,Y27,AA27,AC27,AE27,AG27,AI27,AK27,AM27,AO27,AQ27),-1000) -> -1000 | AT27: =MAX(AS7:AS27) -> -1000
D28: =IF(COUNTIF(D7:D27,">-1000")>0,MIN(D7:D27),-1000) -> -1000 | F28: =IF(COUNTIF(F7:F27,">-1000")>0,MIN(F7:F27),-1000) -> -1000 | H28: =IF(COUNTIF(H7:H27,">-1000")>0,MIN(H7:H27),-1000) -> -1000 | J28: =IF(COUNTIF(J7:J27,">-1000")>0,MIN(J7:J27),-1000) -> -1000 | L28: =IF(COUNTIF(L7:L27,">-1000")>0,MIN(L7:L27),-1000) -> -1000 | N28: =IF(COUNTIF(N7:N27,">-1000")>0,MIN(N7:N27),-1000) -> -1000 | P28: =IF(COUNTIF(P7:P27,">-1000")>0,MIN(P7:P27),-1000) -> -1000 | R28: =IF(COUNTIF(R7:R27,">-1000")>0,MIN(R7:R27),-1000) -> -1000 | T28: =IF(COUNTIF(T7:T27,">-1000")>0,MIN(T7:T27),-1000) -> -1000 | V28: =IF(COUNTIF(V7:V27,">-1000")>0,MIN(V7:V27),-1000) -> -1000 | X28: =IF(COUNTIF(X7:X27,">-1000")>0,MIN(X7:X27),-1000) -> -1000 | Z28: =IF(COUNTIF(Z7:Z27,">-1000")>0,MIN(Z7:Z27),-1000) -> -1000 | AB28: =IF(COUNTIF(AB7:AB27,">-1000")>0,MIN(AB7:AB27),-1000) -> -1000 | AD28: =IF(COUNTIF(AD7:AD27,">-1000")>0,MIN(AD7:AD27),-1000) -> -1000 | AF28: =IF(COUNTIF(AF7:AF27,">-1000")>0,MIN(AF7:AF27),-1000) -> -1000 | AH28: =IF(COUNTIF(AH7:AH27,">-1000")>0,MIN(AH7:AH27),-1000) -> -1000 | AJ28: =IF(COUNTIF(AJ7:AJ27,">-1000")>0,MIN(AJ7:AJ27),-1000) -> -1000 | AL28: =IF(COUNTIF(AL7:AL27,">-1000")>0,MIN(AL7:AL27),-1000) -> -1000 | AN28: =IF(COUNTIF(AN7:AN27,">-1000")>0,MIN(AN7:AN27),-1000) -> -1000 | AP28: =IF(COUNTIF(AP7:AP27,">-1000")>0,MIN(AP7:AP27),-1000) -> -1000 | AR28: =IF(COUNTIF(AR7:AR27,">-1000")>0,MIN(AR7:AR27),-1000) -> -1000
AR29: =MAX(D28,F28,H28,J28,L28,N28,P28,R28,T28,V28,X28,Z28,AB28,AD28,AF28,AH28,AJ28,AL28,AN28,AP28,AR28) -> -1000

Sheet weak dom
G1: WEAK DOMINATION
B2: Weak domination between the rows can be seen in the matrix below, weak domination between the columns in the smaller matrix below that. Weakly dominated rows are columns will be shown in grey only.
C4: the matrix
C5: 1 | D5: 1 | E5: 2 | F5: 2 | G5: 3 | H5: 3 | I5: 4 | J5: 4 | K5: 5 | L5: 5 | M5: 6 | N5: 6 | O5: 7 | P5: 7 | Q5: 8 | R5: 8 | S5: 9 | T5: 9 | U5: 10 | V5: 10 | W5: 11 | X5: 11 | Y5: 12 | Z5: 12 | AA5: 13 | AB5: 13 | AC5: 14 | AD5: 14 | AE5: 15 | AF5: 15 | AG5: 16 | AH5: 16 | AI5: 17 | AJ5: 17 | AK5: 18 | AL5: 18 | AM5: 19 | AN5: 19 | AO5: 20 | AP5: 20 | AQ5: 21 | AR5: 21 | AT5: rows
C6: B1 | D6: B1 | E6: B2 | F6: B2 | G6: B3 | H6: B3 | I6: B4 | J6: B4 | K6: B5 | L6: B5 | M6: B6 | N6: B6 | O6: B7 | P6: B7 | Q6: B8 | R6: B8 | S6: B9 | T6: B9 | U6: B10 | V6: B10 | W6: B11 | X6: B11 | Y6: B12 | Z6: B12 | AA6: B13 | AB6: B13 | AC6: B14 | AD6: B14 | AE6: B15 | AF6: B15 | AG6: B16 | AH6: B16 | AI6: B17 | AJ6: B17 | AK6: B18 | AL6: B18 | AM6: B19 | AN6: B19 | AO6: B20 | AP6: B20 | AQ6: B21 | AR6: B21 | AT6: =21-COUNTIF(AT7:AT27,"empty") -> 0
A7: 1 | B7: A1 | C7: =IF('non-zero-sum'!C7="","",'non-zero-sum'!C7) | D7: =IF('non-zero-sum'!D7="","",'non-zero-sum'!D7) | E7: =IF('non-zero-sum'!E7="","",'non-zero-sum'!E7) | F7: =IF('non-zero-sum'!F7="","",'non-zero-sum'!F7) | G7: =IF('non-zero-sum'!G7="","",'non-zero-sum'!G7) | H7: =IF('non-zero-sum'!H7="","",'non-zero-sum'!H7) | I7: =IF('non-zero-sum'!I7="","",'non-zero-sum'!I7) | J7: =IF('non-zero-sum'!J7="","",'non-zero-sum'!J7) | ... AR7: =IF('non-zero-sum'!AR7="","",'non-zero-sum'!AR7) | AS7: =C54 | AT7: =IF(COUNTIF(C7:AR7,">=-1000")>0,"","empty") -> empty
A8: 2 | B8: A2 | C8: =IF('non-zero-sum'!C8="","",'non-zero-sum'!C8) | D8: =IF('non-zero-sum'!D8="","",'non-zero-sum'!D8) | E8: =IF('non-zero-sum'!E8="","",'non-zero-sum'!E8) | F8: =IF('non-zero-sum'!F8="","",'non-zero-sum'!F8) | G8: =IF('non-zero-sum'!G8="","",'non-zero-sum'!G8) | H8: =IF('non-zero-sum'!H8="","",'non-zero-sum'!H8) | I8: =IF('non-zero-sum'!I8="","",'non-zero-sum'!I8) | J8: =IF('non-zero-sum'!J8="","",'non-zero-sum'!J8) | ... AR8: =IF('non-zero-sum'!AR8="","",'non-zero-sum'!AR8) | AS8: =E54 | AT8: =IF(COUNTIF(C8:AR8,">=-1000")>0,"","empty") -> empty
A9: 3 | B9: A3 | C9: =IF('non-zero-sum'!C9="","",'non-zero-sum'!C9) | D9: =IF('non-zero-sum'!D9="","",'non-zero-sum'!D9) | E9: =IF('non-zero-sum'!E9="","",'non-zero-sum'!E9) | F9: =IF('non-zero-sum'!F9="","",'non-zero-sum'!F9) | G9: =IF('non-zero-sum'!G9="","",'non-zero-sum'!G9) | H9: =IF('non-zero-sum'!H9="","",'non-zero-sum'!H9) | I9: =IF('non-zero-sum'!I9="","",'non-zero-sum'!I9) | J9: =IF('non-zero-sum'!J9="","",'non-zero-sum'!J9) | ... AR9: =IF('non-zero-sum'!AR9="","",'non-zero-sum'!AR9) | AS9: =G54 | AT9: =IF(COUNTIF(C9:AR9,">=-1000")>0,"","empty") -> empty
A10: 4 | B10: A4 | C10: =IF('non-zero-sum'!C10="","",'non-zero-sum'!C10) | D10: =IF('non-zero-sum'!D10="","",'non-zero-sum'!D10) | E10: =IF('non-zero-sum'!E10="","",'non-zero-sum'!E10) | F10: =IF('non-zero-sum'!F10="","",'non-zero-sum'!F10) | G10: =IF('non-zero-sum'!G10="","",'non-zero-sum'!G10) | H10: =IF('non-zero-sum'!H10="","",'non-zero-sum'!H10) | I10: =IF('non-zero-sum'!I10="","",'non-zero-sum'!I10) | J10: =IF('non-zero-sum'!J10="","",'non-zero-sum'!J10) | ... AR10: =IF('non-zero-sum'!AR10="","",'non-zero-sum'!AR10) | AS10: =I54 | AT10: =IF(COUNTIF(C10:AR10,">=-1000")>0,"","empty") -> empty
A11: 5 | B11: A5 | C11: =IF('non-zero-sum'!C11="","",'non-zero-sum'!C11) | D11: =IF('non-zero-sum'!D11="","",'non-zero-sum'!D11) | E11: =IF('non-zero-sum'!E11="","",'non-zero-sum'!E11) | F11: =IF('non-zero-sum'!F11="","",'non-zero-sum'!F11) | G11: =IF('non-zero-sum'!G11="","",'non-zero-sum'!G11) | H11: =IF('non-zero-sum'!H11="","",'non-zero-sum'!H11) | I11: =IF('non-zero-sum'!I11="","",'non-zero-sum'!I11) | J11: =IF('non-zero-sum'!J11="","",'non-zero-sum'!J11) | ... AR11: =IF('non-zero-sum'!AR11="","",'non-zero-sum'!AR11) | AS11: =K54 | AT11: =IF(COUNTIF(C11:AR11,">=-1000")>0,"","empty") -> empty
A12: 6 | B12: A6 | C12: =IF('non-zero-sum'!C12="","",'non-zero-sum'!C12) | D12: =IF('non-zero-sum'!D12="","",'non-zero-sum'!D12) | E12: =IF('non-zero-sum'!E12="","",'non-zero-sum'!E12) | F12: =IF('non-zero-sum'!F12="","",'non-zero-sum'!F12) | G12: =IF('non-zero-sum'!G12="","",'non-zero-sum'!G12) | H12: =IF('non-zero-sum'!H12="","",'non-zero-sum'!H12) | I12: =IF('non-zero-sum'!I12="","",'non-zero-sum'!I12) | J12: =IF('non-zero-sum'!J12="","",'non-zero-sum'!J12) | ... AR12: =IF('non-zero-sum'!AR12="","",'non-zero-sum'!AR12) | AS12: =M54 | AT12: =IF(COUNTIF(C12:AR12,">=-1000")>0,"","empty") -> empty
A13: 7 | B13: A7 | C13: =IF('non-zero-sum'!C13="","",'non-zero-sum'!C13) | D13: =IF('non-zero-sum'!D13="","",'non-zero-sum'!D13) | E13: =IF('non-zero-sum'!E13="","",'non-zero-sum'!E13) | F13: =IF('non-zero-sum'!F13="","",'non-zero-sum'!F13) | G13: =IF('non-zero-sum'!G13="","",'non-zero-sum'!G13) | H13: =IF('non-zero-sum'!H13="","",'non-zero-sum'!H13) | I13: =IF('non-zero-sum'!I13="","",'non-zero-sum'!I13) | J13: =IF('non-zero-sum'!J13="","",'non-zero-sum'!J13) | ... AR13: =IF('non-zero-sum'!AR13="","",'non-zero-sum'!AR13) | AS13: =O54 | AT13: =IF(COUNTIF(C13:AR13,">=-1000")>0,"","empty") -> empty
A14: 8 | B14: A8 | C14: =IF('non-zero-sum'!C14="","",'non-zero-sum'!C14) | D14: =IF('non-zero-sum'!D14="","",'non-zero-sum'!D14) | E14: =IF('non-zero-sum'!E14="","",'non-zero-sum'!E14) | F14: =IF('non-zero-sum'!F14="","",'non-zero-sum'!F14) | G14: =IF('non-zero-sum'!G14="","",'non-zero-sum'!G14) | H14: =IF('non-zero-sum'!H14="","",'non-zero-sum'!H14) | I14: =IF('non-zero-sum'!I14="","",'non-zero-sum'!I14) | J14: =IF('non-zero-sum'!J14="","",'non-zero-sum'!J14) | ... AR14: =IF('non-zero-sum'!AR14="","",'non-zero-sum'!AR14) | AS14: =Q54 | AT14: =IF(COUNTIF(C14:AR14,">=-1000")>0,"","empty") -> empty
A15: 9 | B15: A9 | C15: =IF('non-zero-sum'!C15="","",'non-zero-sum'!C15) | D15: =IF('non-zero-sum'!D15="","",'non-zero-sum'!D15) | E15: =IF('non-zero-sum'!E15="","",'non-zero-sum'!E15) | F15: =IF('non-zero-sum'!F15="","",'non-zero-sum'!F15) | G15: =IF('non-zero-sum'!G15="","",'non-zero-sum'!G15) | H15: =IF('non-zero-sum'!H15="","",'non-zero-sum'!H15) | I15: =IF('non-zero-sum'!I15="","",'non-zero-sum'!I15) | J15: =IF('non-zero-sum'!J15="","",'non-zero-sum'!J15) | ... AR15: =IF('non-zero-sum'!AR15="","",'non-zero-sum'!AR15) | AS15: =S54 | AT15: =IF(COUNTIF(C15:AR15,">=-1000")>0,"","empty") -> empty
A16: 10 | B16: A10 | C16: =IF('non-zero-sum'!C16="","",'non-zero-sum'!C16) | D16: =IF('non-zero-sum'!D16="","",'non-zero-sum'!D16) | E16: =IF('non-zero-sum'!E16="","",'non-zero-sum'!E16) | F16: =IF('non-zero-sum'!F16="","",'non-zero-sum'!F16) | G16: =IF('non-zero-sum'!G16="","",'non-zero-sum'!G16) | H16: =IF('non-zero-sum'!H16="","",'non-zero-sum'!H16) | I16: =IF('non-zero-sum'!I16="","",'non-zero-sum'!I16) | J16: =IF('non-zero-sum'!J16="","",'non-zero-sum'!J16) | ... AR16: =IF('non-zero-sum'!AR16="","",'non-zero-sum'!AR16) | AS16: =U54 | AT16: =IF(COUNTIF(C16:AR16,">=-1000")>0,"","empty") -> empty
A17: 11 | B17: A11 | C17: =IF('non-zero-sum'!C17="","",'non-zero-sum'!C17) | D17: =IF('non-zero-sum'!D17="","",'non-zero-sum'!D17) | E17: =IF('non-zero-sum'!E17="","",'non-zero-sum'!E17) | F17: =IF('non-zero-sum'!F17="","",'non-zero-sum'!F17) | G17: =IF('non-zero-sum'!G17="","",'non-zero-sum'!G17) | H17: =IF('non-zero-sum'!H17="","",'non-zero-sum'!H17) | I17: =IF('non-zero-sum'!I17="","",'non-zero-sum'!I17) | J17: =IF('non-zero-sum'!J17="","",'non-zero-sum'!J17) | ... AR17: =IF('non-zero-sum'!AR17="","",'non-zero-sum'!AR17) | AS17: =W54 | AT17: =IF(COUNTIF(C17:AR17,">=-1000")>0,"","empty") -> empty
A18: 12 | B18: A12 | C18: =IF('non-zero-sum'!C18="","",'non-zero-sum'!C18) | D18: =IF('non-zero-sum'!D18="","",'non-zero-sum'!D18) | E18: =IF('non-zero-sum'!E18="","",'non-zero-sum'!E18) | F18: =IF('non-zero-sum'!F18="","",'non-zero-sum'!F18) | G18: =IF('non-zero-sum'!G18="","",'non-zero-sum'!G18) | H18: =IF('non-zero-sum'!H18="","",'non-zero-sum'!H18) | I18: =IF('non-zero-sum'!I18="","",'non-zero-sum'!I18) | J18: =IF('non-zero-sum'!J18="","",'non-zero-sum'!J18) | ... AR18: =IF('non-zero-sum'!AR18="","",'non-zero-sum'!AR18) | AS18: =Y54 | AT18: =IF(COUNTIF(C18:AR18,">=-1000")>0,"","empty") -> empty
A19: 13 | B19: A13 | C19: =IF('non-zero-sum'!C19="","",'non-zero-sum'!C19) | D19: =IF('non-zero-sum'!D19="","",'non-zero-sum'!D19) | E19: =IF('non-zero-sum'!E19="","",'non-zero-sum'!E19) | F19: =IF('non-zero-sum'!F19="","",'non-zero-sum'!F19) | G19: =IF('non-zero-sum'!G19="","",'non-zero-sum'!G19) | H19: =IF('non-zero-sum'!H19="","",'non-zero-sum'!H19) | I19: =IF('non-zero-sum'!I19="","",'non-zero-sum'!I19) | J19: =IF('non-zero-sum'!J19="","",'non-zero-sum'!J19) | ... AR19: =IF('non-zero-sum'!AR19="","",'non-zero-sum'!AR19) | AS19: =AA54 | AT19: =IF(COUNTIF(C19:AR19,">=-1000")>0,"","empty") -> empty
A20: 14 | B20: A14 | C20: =IF('non-zero-sum'!C20="","",'non-zero-sum'!C20) | D20: =IF('non-zero-sum'!D20="","",'non-zero-sum'!D20) | E20: =IF('non-zero-sum'!E20="","",'non-zero-sum'!E20) | F20: =IF('non-zero-sum'!F20="","",'non-zero-sum'!F20) | G20: =IF('non-zero-sum'!G20="","",'non-zero-sum'!G20) | H20: =IF('non-zero-sum'!H20="","",'non-zero-sum'!H20) | I20: =IF('non-zero-sum'!I20="","",'non-zero-sum'!I20) | J20: =IF('non-zero-sum'!J20="","",'non-zero-sum'!J20) | ... AR20: =IF('non-zero-sum'!AR20="","",'non-zero-sum'!AR20) | AS20: =AC54 | AT20: =IF(COUNTIF(C20:AR20,">=-1000")>0,"","empty") -> empty
A21: 15 | B21: A15 | C21: =IF('non-zero-sum'!C21="","",'non-zero-sum'!C21) | D21: =IF('non-zero-sum'!D21="","",'non-zero-sum'!D21) | E21: =IF('non-zero-sum'!E21="","",'non-zero-sum'!E21) | F21: =IF('non-zero-sum'!F21="","",'non-zero-sum'!F21) | G21: =IF('non-zero-sum'!G21="","",'non-zero-sum'!G21) | H21: =IF('non-zero-sum'!H21="","",'non-zero-sum'!H21) | I21: =IF('non-zero-sum'!I21="","",'non-zero-sum'!I21) | J21: =IF('non-zero-sum'!J21="","",'non-zero-sum'!J21) | ... AR21: =IF('non-zero-sum'!AR21="","",'non-zero-sum'!AR21) | AS21: =AE54 | AT21: =IF(COUNTIF(C21:AR21,">=-1000")>0,"","empty") -> empty
A22: 16 | B22: A16 | C22: =IF('non-zero-sum'!C22="","",'non-zero-sum'!C22) | D22: =IF('non-zero-sum'!D22="","",'non-zero-sum'!D22) | E22: =IF('non-zero-sum'!E22="","",'non-zero-sum'!E22) | F22: =IF('non-zero-sum'!F22="","",'non-zero-sum'!F22) | G22: =IF('non-zero-sum'!G22="","",'non-zero-sum'!G22) | H22: =IF('non-zero-sum'!H22="","",'non-zero-sum'!H22) | I22: =IF('non-zero-sum'!I22="","",'non-zero-sum'!I22) | J22: =IF('non-zero-sum'!J22="","",'non-zero-sum'!J22) | ... AR22: =IF('non-zero-sum'!AR22="","",'non-zero-sum'!AR22) | AS22: =AG54 | AT22: =IF(COUNTIF(C22:AR22,">=-1000")>0,"","empty") -> empty
A23: 17 | B23: A17 | C23: =IF('non-zero-sum'!C23="","",'non-zero-sum'!C23) | D23: =IF('non-zero-sum'!D23="","",'non-zero-sum'!D23) | E23: =IF('non-zero-sum'!E23="","",'non-zero-sum'!E23) | F23: =IF('non-zero-sum'!F23="","",'non-zero-sum'!F23) | G23: =IF('non-zero-sum'!G23="","",'non-zero-sum'!G23) | H23: =IF('non-zero-sum'!H23="","",'non-zero-sum'!H23) | I23: =IF('non-zero-sum'!I23="","",'non-zero-sum'!I23) | J23: =IF('non-zero-sum'!J23="","",'non-zero-sum'!J23) | ... AR23: =IF('non-zero-sum'!AR23="","",'non-zero-sum'!AR23) | AS23: =AI54 | AT23: =IF(COUNTIF(C23:AR23,">=-1000")>0,"","empty") -> empty
A24: 18 | B24: A18 | C24: =IF('non-zero-sum'!C24="","",'non-zero-sum'!C24) | D24: =IF('non-zero-sum'!D24="","",'non-zero-sum'!D24) | E24: =IF('non-zero-sum'!E24="","",'non-zero-sum'!E24) | F24: =IF('non-zero-sum'!F24="","",'non-zero-sum'!F24) | G24: =IF('non-zero-sum'!G24="","",'non-zero-sum'!G24) | H24: =IF('non-zero-sum'!H24="","",'non-zero-sum'!H24) | I24: =IF('non-zero-sum'!I24="","",'non-zero-sum'!I24) | J24: =IF('non-zero-sum'!J24="","",'non-zero-sum'!J24) | ... AR24: =IF('non-zero-sum'!AR24="","",'non-zero-sum'!AR24) | AS24: =AK54 | AT24: =IF(COUNTIF(C24:AR24,">=-1000")>0,"","empty") -> empty
A25: 19 | B25: A19 | C25: =IF('non-zero-sum'!C25="","",'non-zero-sum'!C25) | D25: =IF('non-zero-sum'!D25="","",'non-zero-sum'!D25) | E25: =IF('non-zero-sum'!E25="","",'non-zero-sum'!E25) | F25: =IF('non-zero-sum'!F25="","",'non-zero-sum'!F25) | G25: =IF('non-zero-sum'!G25="","",'non-zero-sum'!G25) | H25: =IF('non-zero-sum'!H25="","",'non-zero-sum'!H25) | I25: =IF('non-zero-sum'!I25="","",'non-zero-sum'!I25) | J25: =IF('non-zero-sum'!J25="","",'non-zero-sum'!J25) | ... AR25: =IF('non-zero-sum'!AR25="","",'non-zero-sum'!AR25) | AS25: =AM54 | AT25: =IF(COUNTIF(C25:AR25,">=-1000")>0,"","empty") -> empty
A26: 20 | B26: A20 | C26: =IF('non-zero-sum'!C26="","",'non-zero-sum'!C26) | D26: =IF('non-zero-sum'!D26="","",'non-zero-sum'!D26) | E26: =IF('non-zero-sum'!E26="","",'non-zero-sum'!E26) | F26: =IF('non-zero-sum'!F26="","",'non-zero-sum'!F26) | G26: =IF('non-zero-sum'!G26="","",'non-zero-sum'!G26) | H26: =IF('non-zero-sum'!H26="","",'non-zero-sum'!H26) | I26: =IF('non-zero-sum'!I26="","",'non-zero-sum'!I26) | J26: =IF('non-zero-sum'!J26="","",'non-zero-sum'!J26) | ... AR26: =IF('non-zero-sum'!AR26="","",'non-zero-sum'!AR26) | AS26: =AO54 | AT26: =IF(COUNTIF(C26:AR26,">=-1000")>0,"","empty") -> empty
A27: 21 | B27: A21 | C27: =IF('non-zero-sum'!C27="","",'non-zero-sum'!C27) | D27: =IF('non-zero-sum'!D27="","",'non-zero-sum'!D27) | E27: =IF('non-zero-sum'!E27="","",'non-zero-sum'!E27) | F27: =IF('non-zero-sum'!F27="","",'non-zero-sum'!F27) | G27: =IF('non-zero-sum'!G27="","",'non-zero-sum'!G27) | H27: =IF('non-zero-sum'!H27="","",'non-zero-sum'!H27) | I27: =IF('non-zero-sum'!I27="","",'non-zero-sum'!I27) | J27: =IF('non-zero-sum'!J27="","",'non-zero-sum'!J27) | ... AR27: =IF('non-zero-sum'!AR27="","",'non-zero-sum'!AR27) | AS27: =AQ54 | AT27: =IF(COUNTIF(C27:AR27,">=-1000")>0,"","empty") -> empty
D28: =IF(C80="dominated","dominated","") | F28: =IF(D80="dominated","dominated","") | H28: =IF(E80="dominated","dominated","") | J28: =IF(F80="dominated","dominated","") | L28: =IF(G80="dominated","dominated","") | N28: =IF(H80="dominated","dominated","") | P28: =IF(I80="dominated","dominated","") | R28: =IF(J80="dominated","dominated","") | T28: =IF(K80="dominated","dominated","") | V28: =IF(L80="dominated","dominated","") | X28: =IF(M80="dominated","dominated","") | Z28: =IF(N80="dominated","dominated","") | AB28: =IF(O80="dominated","dominated","") | AD28: =IF(P80="dominated","dominated","") | AF28: =IF(Q80="dominated","dominated","") | AH28: =IF(R80="dominated","dominated","") | AJ28: =IF(S80="dominated","dominated","") | AL28: =IF(T80="dominated","dominated","") | AN28: =IF(U80="dominated","dominated","") | AP28: =IF(V80="dominated","dominated","") | AR28: =IF(W80="dominated","dominated","")
A29: columns | B29: =21-COUNTIF(C29:AR29,"empty") -> 0 | C29: =IF(COUNTIF(C7:C27,">=-1000")>0,"","empty") -> empty | E29: =IF(COUNTIF(E7:E27,">=-1000")>0,"","empty") -> empty | G29: =IF(COUNTIF(G7:G27,">=-1000")>0,"","empty") -> empty | I29: =IF(COUNTIF(I7:I27,">=-1000")>0,"","empty") -> empty | K29: =IF(COUNTIF(K7:K27,">=-1000")>0,"","empty") -> empty | M29: =IF(COUNTIF(M7:M27,">=-1000")>0,"","empty") -> empty | O29: =IF(COUNTIF(O7:O27,">=-1000")>0,"","empty") -> empty | Q29: =IF(COUNTIF(Q7:Q27,">=-1000")>0,"","empty") -> empty | S29: =IF(COUNTIF(S7:S27,">=-1000")>0,"","empty") -> empty | U29: =IF(COUNTIF(U7:U27,">=-1000")>0,"","empty") -> empty | W29: =IF(COUNTIF(W7:W27,">=-1000")>0,"","empty") -> empty | Y29: =IF(COUNTIF(Y7:Y27,">=-1000")>0,"","empty") -> empty | AA29: =IF(COUNTIF(AA7:AA27,">=-1000")>0,"","empty") -> empty | AC29: =IF(COUNTIF(AC7:AC27,">=-1000")>0,"","empty") -> empty | AE29: =IF(COUNTIF(AE7:AE27,">=-1000")>0,"","empty") -> empty | AG29: =IF(COUNTIF(AG7:AG27,">=-1000")>0,"","empty") -> empty | AI29: =IF(COUNTIF(AI7:AI27,">=-1000")>0,"","empty") -> empty | AK29: =IF(COUNTIF(AK7:AK27,">=-1000")>0,"","empty") -> empty | AM29: =IF(COUNTIF(AM7:AM27,">=-1000")>0,"","empty") -> empty | AO29: =IF(COUNTIF(AO7:AO27,">=-1000")>0,"","empty") -> empty | AQ29: =IF(COUNTIF(AQ7:AQ27,">=-1000")>0,"","empty") -> empty
AU30: The transposed Matrix
C31: 1 | D31: 1 | E31: 2 | F31: 2 | G31: 3 | H31: 3 | I31: 4 | J31: 4 | K31: 5 | L31: 5 | M31: 6 | N31: 6 | O31: 7 | P31: 7 | Q31: 8 | R31: 8 | S31: 9 | T31: 9 | U31: 10 | V31: 10 | W31: 11 | X31: 11 | Y31: 12 | Z31: 12 | AA31: 13 | AB31: 13 | AC31: 14 | AD31: 14 | AE31: 15 | AF31: 15 | AG31: 16 | AH31: 16 | AI31: 17 | AJ31: 17 | AK31: 18 | AL31: 18 | AM31: 19 | AN31: 19 | AO31: 20 | AP31: 20 | AQ31: 21 | AR31: 21 | AW31: 1 | AX31: 1 | AY31: 2 | AZ31: 2 | BA31: 3 | BB31: 3 | BC31: 4 | BD31: 4 | BE31: 5 | BF31: 5 | BG31: 6 | BH31: 6 | BI31: 7 | BJ31: 7 | BK31: 8 | BL31: 8 | BM31: 9 | BN31: 9 | BO31: 10 | BP31: 10 | BQ31: 11 | BR31: 11 | BS31: 12 | BT31: 12 | BU31: 13 | BV31: 13 | BW31: 14 | BX31: 14 | BY31: 15 | BZ31: 15 | CA31: 16 | CB31: 16 | CC31: 17 | CD31: 17 | CE31: 18 | CF31: 18 | CG31: 19 | CH31: 19 | CI31: 20 | CJ31: 20 | CK31: 21 | CL31: 21
B32: rows | C32: A1 | E32: A2 | G32: A3 | I32: A4 | K32: A5 | M32: A6 | O32: A7 | Q32: A8 | S32: A9 | U32: A10 | W32: A11 | Y32: A12 | AA32: A13 | AC32: A14 | AE32: A15 | AG32: A16 | AI32: A17 | AK32: A18 | AM32: A19 | AO32: A20 | AQ32: A21 | AV32: rows | AW32: A1 | AY32: A2 | BA32: A3 | BC32: A4 | BE32: A5 | BG32: A6 | BI32: A7 | BK32: A8 | BM32: A9 | BO32: A10 | BQ32: A11 | BS32: A12 | BU32: A13 | BW32: A14 | BY32: A15 | CA32: A16 | CC32: A17 | CE32: A18 | CG32: A19 | CI32: A20 | CK32: A21
